Workbook
Name solver_adj: 'OTIMIZA ROTA'!$L$68:$Q$73,'OTIMIZA ROTA'!$L$78:$Q$83,'OTIMIZA ROTA'!$L$88:$Q$93
Name solver_cvg: 0.0001
Name solver_cvg: 0.0001
Name solver_drv: 1
Name solver_drv: 1
Name solver_eng: 2
Name solver_eng: 3
Name solver_est: 1
Name solver_est: 1
Name solver_itr: 2147483647
Name solver_itr: 2147483647
Name solver_mip: 2147483647
Name solver_mip: 2147483647
Name solver_mni: 30
Name solver_mni: 30
Name solver_mrt: 0.075
Name solver_mrt: 0.075
Name solver_msl: 2
Name solver_msl: 2
Name solver_neg: 1
Name solver_neg: 2
Name solver_nod: 2147483647
Name solver_nod: 2147483647
Name solver_num: 29
Name solver_num: 4
Name solver_nwt: 1
Name solver_nwt: 1
Name solver_pre: 0.000001
Name solver_pre: 0.000001
Name solver_rbv: 1
Name solver_rbv: 1
Name solver_rel1: 3
Name solver_rel1: 3
Name solver_rel10: 3
Name solver_rel11: 3
Name solver_rel12: 3
Name solver_rel13: 3
Name solver_rel14: 1
Name solver_rel15: 1
Name solver_rel16: 1
Name solver_rel17: 1
Name solver_rel18: 1
Name solver_rel19: 2
Name solver_rel2: 3
Name solver_rel2: 1
Name solver_rel20: 2
Name solver_rel21: 2
Name solver_rel22: 2
Name solver_rel23: 2
Name solver_rel24: 2
Name solver_rel25: 2
Name solver_rel26: 2
Name solver_rel27: 2
Name solver_rel28: 3
Name solver_rel29: 3
Name solver_rel3: 3
Name solver_rel3: 1
Name solver_rel30: 1
Name solver_rel31: 1
Name solver_rel32: 1

Sheet ANTAQ 2022 Container
B2: Month | C2: Type | D2: UF Origin | E2: UF Destination | F2: TEU | G2: Unit
B3: jan | C3: 40HC | D3: SP | E3: PE | F3: 3468 | G3: 1734
B4: jan | C4: 40HC | D4: RJ | E4: ES | F4: 3400 | G4: 1700
B5: jan | C5: 40HC | D5: SP | E5: PR | F5: 3106 | G5: 1553
B6: jan | C6: 40HC | D6: SP | E6: ES | F6: 2858 | G6: 1429
B7: jan | C7: 40HC | D7: SP | E7: AM | F7: 2776 | G7: 1388
B8: jan | C8: 40HC | D8: PE | E8: AM | F8: 2770 | G8: 1385 | J8: Mês | K8: jan | L8: fev | M8: mar | N8: abr | O8: mai | P8: jun | Q8: jul | R8: ago | S8: set | T8: out | U8: nov | V8: dez | W8: Total Geral
B9: jan | C9: 40HC | D9: AM | E9: SP | F9: 2714 | G9: 1357 | J9: TEU | K9: 81649 | L9: 83841 | M9: 102020 | N9: 91011 | O9: 104467 | P9: 97384 | Q9: 105192 | R9: 100343 | S9: 99251 | T9: 99655 | U9: 86179 | V9: 87708 | W9: 1138700
B10: jan | C10: 40HC | D10: AM | E10: SP | F10: 2414 | G10: 1207
B11: jan | C11: 40HC | D11: SP | E11: CE | F11: 2364 | G11: 1182
B12: jan | C12: 20DC | D12: ES | E12: RJ | F12: 2297 | G12: 2297
B13: jan | C13: 40HC | D13: AM | E13: PE | F13: 1802 | G13: 901
B14: jan | C14: 40HC | D14: CE | E14: AM | F14: 1628 | G14: 814
B15: jan | C15: 40RH | D15: SC | E15: AM | F15: 1328 | G15: 664
B16: jan | C16: 40HC | D16: SC | E16: CE | F16: 1318 | G16: 659
B17: jan | C17: 40HC | D17: SC | E17: AM | F17: 1316 | G17: 658
B18: jan | C18: 40HC | D18: SC | E18: PE | F18: 1214 | G18: 607
B19: jan | C19: 40HC | D19: PE | E19: SP | F19: 1208 | G19: 604
B20: jan | C20: 20DC | D20: SP | E20: PR | F20: 1002 | G20: 1002
B21: jan | C21: 40HC | D21: PE | E21: RJ | F21: 970 | G21: 485
... B5374: dez | C5374: 20DC | D5374: SP | E5374: SC | F5374: 1 | G5374: 1

Sheet Pivot Container
O2: Movimentação de Contêineres na Cabotagem em 2022 - 20DC | AD2: Imbalance 20DC
O3: Origem/Destino | P3: AM | Q3: PA | R3: MA | S3: CE | T3: PE | U3: BA | V3: ES | W3: RJ | X3: SP | Y3: PR | Z3: SC | AA3: RS | AB3: Total Origem | AD3: Porto | AE3: In | AF3: Out | AG3: IMB
O4: AM | R4: 1 | S4: 1747 | T4: 313 | U4: 329 | W4: 1002 | X4: 2513 | Z4: 475 | AA4: 19 | AB4: =SUM(P4:AA4) -> 6399 | AD4: AM | AE4: =P16 -> 13472 | AF4: =AB4 -> 6399 | AG4: =AE4-AF4 -> 7073
O5: PA | S5: 3833 | U5: 50 | X5: 3453 | Z5: 33 | AA5: 25 | AB5: =SUM(P5:AA5) -> 7394 | AD5: PA | AE5: =Q16 -> 327 | AF5: =AB5 -> 7394 | AG5: =AE5-AF5 -> -7067
O6: MA | S6: 9 | AA6: 9 | AB6: =SUM(P6:AA6) -> 18 | AD6: MA | AE6: =R16 -> 1601 | AF6: =AB6 -> 18 | AG6: =AE6-AF6 -> 1583
O7: CE | P7: 2926 | Q7: 327 | R7: 22 | T7: 282 | U7: 491 | W7: 1239 | X7: 9135 | Z7: 4055 | AA7: 432 | AB7: =SUM(P7:AA7) -> 18909 | AD7: CE | AE7: =S16 -> 34483 | AF7: =AB7 -> 18909 | AG7: =AE7-AF7 -> 15574
O8: PE | P8: 2039 | R8: 1 | S8: 1481 | U8: 2967 | V8: 17 | W8: 1887 | X8: 8519 | Y8: 1 | Z8: 827 | AA8: 264 | AB8: =SUM(P8:AA8) -> 18003 | AD8: PE | AE8: =T16 -> 27865 | AF8: =AB8 -> 18003 | AG8: =AE8-AF8 -> 9862
O9: BA | P9: 407 | S9: 779 | T9: 670 | V9: 11 | W9: 565 | X9: 10907 | Y9: 56 | Z9: 289 | AA9: 145 | AB9: =SUM(P9:AA9) -> 13829 | AD9: BA | AE9: =U16 -> 14720 | AF9: =AB9 -> 13829 | AG9: =AE9-AF9 -> 891
O10: ES | P10: 652 | T10: 39 | W10: 38075 | X10: 5566 | Z10: 55 | AA10: 2 | AB10: =SUM(P10:AA10) -> 44389 | AD10: ES | AE10: =V16 -> 14162 | AF10: =AB10 -> 44389 | AG10: =AE10-AF10 -> -30227
O11: RJ | P11: 1770 | S11: 322 | T11: 517 | U11: 663 | V11: 9148 | X11: 1315 | Y11: 95 | Z11: 761 | AB11: =SUM(P11:AA11) -> 14591 | AD11: RJ | AE11: =W16 -> 47784 | AF11: =AB11 -> 14591 | AG11: =AE11-AF11 -> 33193
O12: SP | P12: 4058 | R12: 31 | S12: 6369 | T12: 6570 | U12: 2077 | V12: 4986 | W12: 4217 | Y12: 8785 | Z12: 4563 | AB12: =SUM(P12:AA12) -> 41656 | AD12: SP | AE12: =X16 -> 42126 | AF12: =AB12 -> 41656 | AG12: =AE12-AF12 -> 470
O13: PR | S13: 11 | U13: 11 | W13: 3 | X13: 1 | Z13: 455 | AB13: =SUM(P13:AA13) -> 481 | AD13: PR | AE13: =Y16 -> 10534 | AF13: =AB13 -> 481 | AG13: =AE13-AF13 -> 10053
O14: SC | P14: 1452 | R14: 346 | S14: 11836 | T14: 13601 | U14: 4203 | W14: 778 | X14: 256 | Y14: 1573 | Z14: 803 | AA14: 6 | AB14: =SUM(P14:AA14) -> 34854 | AD14: SC | AE14: =Z16 -> 12703 | AF14: =AB14 -> 34854 | AG14: =AE14-AF14 -> -22151
O15: RS | P15: 168 | R15: 1200 | S15: 8096 | T15: 5873 | U15: 3929 | W15: 18 | X15: 461 | Y15: 24 | Z15: 387 | AB15: =SUM(P15:AA15) -> 20156 | AD15: RS | AE15: =AA16 -> 902 | AF15: =AB15 -> 20156 | AG15: =AE15-AF15 -> -19254
O16: Total Destino | P16: =SUM(P4:P15) -> 13472 | Q16: =SUM(Q4:Q15) -> 327 | R16: =SUM(R4:R15) -> 1601 | S16: =SUM(S4:S15) -> 34483 | T16: =SUM(T4:T15) -> 27865 | U16: =SUM(U4:U15) -> 14720 | V16: =SUM(V4:V15) -> 14162 | W16: =SUM(W4:W15) -> 47784 | ... AB16: =SUM(AB4:AB15) -> 220679 | AD16: Total | AE16: =SUM(AE4:AE15) -> 220679 | AF16: =SUM(AF4:AF15) -> 220679 | AG16: =ABS(AG4)+ABS(AG5)+ABS(AG6)+ABS(AG7)+ABS(AG8)+ABS(AG9)+ABS(AG10)+ABS(AG11)+ABS(AG12)+ABS(AG13)+ABS(AG14)+ABS(AG15) -> 157398
O18: Movimentação de Contêineres na Cabotagem em 2022 - 20RF | AD18: Imbalance 20RF
O19: Origem/Destino | P19: AM | Q19: PA | R19: MA | S19: CE | T19: PE | U19: BA | V19: ES | W19: RJ | X19: SP | Y19: PR | Z19: SC | AA19: RS | AB19: Total Origem | AD19: Porto | AE19: In | AF19: Out | AG19: IMB
O20: AM | T20: 1 | U20: 2 | AB20: =SUM(P20:AA20) -> 3 | AD20: AM | AE20: =P32 -> 0 | AF20: =AB20 -> 3 | AG20: =AE20-AF20 -> -3
O21: PA | AB21: =SUM(P21:AA21) -> 0 | AD21: PA | AE21: =Q32 -> 0 | AF21: =AB21 -> 0 | AG21: =AE21-AF21 -> 0
O22: MA | AB22: =SUM(P22:AA22) -> 0 | AD22: MA | AE22: =R32 -> 0 | AF22: =AB22 -> 0 | AG22: =AE22-AF22 -> 0
O23: CE | AB23: =SUM(P23:AA23) -> 0 | AD23: CE | AE23: =S32 -> 33 | AF23: =AB23 -> 0 | AG23: =AE23-AF23 -> 33
O24: PE | S24: 3 | X24: 1 | Z24: 4 | AB24: =SUM(P24:AA24) -> 8 | AD24: PE | AE24: =T32 -> 29 | AF24: =AB24 -> 8 | AG24: =AE24-AF24 -> 21
O25: BA | S25: 4 | T25: 2 | X25: 2 | Z25: 2 | AB25: =SUM(P25:AA25) -> 10 | AD25: BA | AE25: =U32 -> 4 | AF25: =AB25 -> 10 | AG25: =AE25-AF25 -> -6
O26: ES | W26: 2 | X26: 9 | Z26: 1 | AB26: =SUM(P26:AA26) -> 12 | AD26: ES | AE26: =V32 -> 0 | AF26: =AB26 -> 12 | AG26: =AE26-AF26 -> -12
O27: RJ | S27: 1 | X27: 1 | Y27: 1 | Z27: 1 | AB27: =SUM(P27:AA27) -> 4 | AD27: RJ | AE27: =W32 -> 8 | AF27: =AB27 -> 4 | AG27: =AE27-AF27 -> 4
O28: SP | S28: 17 | T28: 16 | U28: 2 | W28: 5 | Y28: 24 | Z28: 6 | AB28: =SUM(P28:AA28) -> 70 | AD28: SP | AE28: =X32 -> 13 | AF28: =AB28 -> 70 | AG28: =AE28-AF28 -> -57
O29: PR | AB29: =SUM(P29:AA29) -> 0 | AD29: PR | AE29: =Y32 -> 35 | AF29: =AB29 -> 0 | AG29: =AE29-AF29 -> 35
O30: SC | S30: 7 | T30: 9 | W30: 1 | Y30: 10 | Z30: 1 | AB30: =SUM(P30:AA30) -> 28 | AD30: SC | AE30: =Z32 -> 16 | AF30: =AB30 -> 28 | AG30: =AE30-AF30 -> -12
O31: RS | S31: 1 | T31: 1 | Z31: 1 | AB31: =SUM(P31:AA31) -> 3 | AD31: RS | AE31: =AA32 -> 0 | AF31: =AB31 -> 3 | AG31: =AE31-AF31 -> -3
O32: Total Destino | P32: =SUM(P20:P31) -> 0 | Q32: =SUM(Q20:Q31) -> 0 | R32: =SUM(R20:R31) -> 0 | S32: =SUM(S20:S31) -> 33 | T32: =SUM(T20:T31) -> 29 | U32: =SUM(U20:U31) -> 4 | V32: =SUM(V20:V31) -> 0 | W32: =SUM(W20:W31) -> 8 | ... AB32: =SUM(AB20:AB31) -> 138 | AD32: Total | AE32: =SUM(AE20:AE31) -> 138 | AF32: =SUM(AF20:AF31) -> 138 | AG32: =ABS(AG20)+ABS(AG21)+ABS(AG22)+ABS(AG23)+ABS(AG24)+ABS(AG25)+ABS(AG26)+ABS(AG27)+ABS(AG28)+ABS(AG29)+ABS(AG30)+ABS(AG31) -> 186
O34: Movimentação de Contêineres na Cabotagem em 2022 - 40HC | AD34: Imbalance 40HC
O35: Origem/Destino | P35: AM | Q35: PA | R35: MA | S35: CE | T35: PE | U35: BA | V35: ES | W35: RJ | X35: SP | Y35: PR | Z35: SC | AA35: RS | AB35: Total Origem | AD35: Porto | AE35: In | AF35: Out | AG35: IMB
O36: AM | R36: 9 | S36: 6066 | T36: 8232 | U36: 3166 | W36: 7014 | X36: 54983 | Y36: 3 | Z36: 5501 | AA36: 699 | AB36: =SUM(P36:AA36) -> 85673 | AD36: AM | AE36: =P48 -> 66942 | AF36: =AB36 -> 85673 | AG36: =AE36-AF36 -> -18731
O37: PA | S37: 1805 | U37: 4 | X37: 704 | Z37: 92 | AA37: 6 | AB37: =SUM(P37:AA37) -> 2611 | AD37: PA | AE37: =Q48 -> 986 | AF37: =AB37 -> 2611 | AG37: =AE37-AF37 -> -1625
O38: MA | S38: 51 | X38: 52 | AA38: 3 | AB38: =SUM(P38:AA38) -> 106 | AD38: MA | AE38: =R48 -> 2511 | AF38: =AB38 -> 106 | AG38: =AE38-AF38 -> 2405
O39: CE | P39: 10303 | Q39: 985 | R39: 157 | T39: 2481 | U39: 101 | W39: 462 | X39: 7856 | Z39: 3188 | AA39: 366 | AB39: =SUM(P39:AA39) -> 25899 | AD39: CE | AE39: =S48 -> 57391 | AF39: =AB39 -> 25899 | AG39: =AE39-AF39 -> 31492
O40: PE | P40: 17515 | R40: 405 | S40: 5046 | U40: 652 | V40: 103 | W40: 1554 | X40: 9764 | Z40: 4287 | AA40: 963 | AB40: =SUM(P40:AA40) -> 40289 | AD40: PE | AE40: =T48 -> 70371 | AF40: =AB40 -> 40289 | AG40: =AE40-AF40 -> 30082
O41: BA | P41: 3252 | R41: 82 | S41: 2029 | T41: 1364 | V41: 58 | W41: 1612 | X41: 10648 | Y41: 100 | Z41: 2531 | AA41: 490 | AB41: =SUM(P41:AA41) -> 22166 | AD41: BA | AE41: =U48 -> 16952 | AF41: =AB41 -> 22166 | AG41: =AE41-AF41 -> -5214
O42: ES | P42: 933 | T42: 11 | W42: 3802 | X42: 2419 | Z42: 31 | AA42: 8 | AB42: =SUM(P42:AA42) -> 7204 | AD42: ES | AE42: =V48 -> 30266 | AF42: =AB42 -> 7204 | AG42: =AE42-AF42 -> 23062
O43: RJ | P43: 3272 | R43: 10 | S43: 1358 | T43: 5765 | U43: 3757 | V43: 17898 | X43: 2957 | Y43: 102 | Z43: 1095 | AA43: 2 | AB43: =SUM(P43:AA43) -> 36216 | AD43: RJ | AE43: =W48 -> 22587 | AF43: =AB43 -> 36216 | AG43: =AE43-AF43 -> -13629
...

Sheet PROSPECÇÃO VISUAL
B2: Movimentação de Contêineres na Cabotagem em 2022 - 20DC | P2: * feeder desconsiderado
B3: Origem/Destino | C3: AM | D3: PA | E3: MA | F3: CE | G3: PE | H3: BA | I3: ES | J3: RJ | K3: SP | L3: PR | M3: SC | N3: RS | O3: Total Origem | P3: *seleciondas as seis maiores movientações
B4: AM | E4: 1 | F4: 1747 | G4: 313 | H4: 329 | J4: 1002 | K4: 2513 | M4: 475 | N4: 19 | O4: =SUM(C4:N4) -> 6399
B5: PA | F5: 3833 | H5: 50 | K5: 3453 | M5: 33 | N5: 25 | O5: =SUM(C5:N5) -> 7394
B6: MA | F6: 9 | N6: 9 | O6: =SUM(C6:N6) -> 18
B7: CE | C7: 2926 | D7: 327 | E7: 22 | G7: 282 | H7: 491 | J7: 1239 | K7: 9135 | M7: 4055 | N7: 432 | O7: =SUM(C7:N7) -> 18909
B8: PE | C8: 2039 | E8: 1 | F8: 1481 | H8: 2967 | I8: 17 | J8: 1887 | K8: 8519 | L8: 1 | M8: 827 | N8: 264 | O8: =SUM(C8:N8) -> 18003
B9: BA | C9: 407 | F9: 779 | G9: 670 | I9: 11 | J9: 565 | K9: 10907 | L9: 56 | M9: 289 | N9: 145 | O9: =SUM(C9:N9) -> 13829
B10: ES | C10: 652 | G10: 39 | O10: =SUM(C10:N10) -> 691
B11: RJ | C11: 1770 | F11: 322 | G11: 517 | H11: 663 | O11: =SUM(C11:N11) -> 3272
B12: SP | C12: 4058 | E12: 31 | F12: 6369 | G12: 6570 | H12: 2077 | O12: =SUM(C12:N12) -> 19105
B13: PR | F13: 11 | H13: 11 | O13: =SUM(C13:N13) -> 22
B14: SC | C14: 1452 | E14: 346 | F14: 11836 | G14: 13601 | H14: 4203 | O14: =SUM(C14:N14) -> 31438
B15: RS | C15: 168 | E15: 1200 | F15: 8096 | G15: 5873 | H15: 3929 | O15: =SUM(C15:N15) -> 19266
B16: Total Destino | C16: =SUM(C4:C15) -> 13472 | D16: =SUM(D4:D15) -> 327 | E16: =SUM(E4:E15) -> 1601 | F16: =SUM(F4:F15) -> 34483 | G16: =SUM(G4:G15) -> 27865 | H16: =SUM(H4:H15) -> 14720 | I16: =SUM(I4:I15) -> 28 | J16: =SUM(J4:J15) -> 4693 | ... O16: =SUM(O4:O15) -> 138346
B18: Movimentação de Contêineres na Cabotagem em 2022 - 20RF
B19: Origem/Destino | C19: AM | D19: PA | E19: MA | F19: CE | G19: PE | H19: BA | I19: ES | J19: RJ | K19: SP | L19: PR | M19: SC | N19: RS | O19: Total Origem
B20: AM | G20: 1 | H20: 2 | O20: =SUM(C20:N20) -> 3
B21: PA | O21: =SUM(C21:N21) -> 0
B22: MA | O22: =SUM(C22:N22) -> 0
B23: CE | O23: =SUM(C23:N23) -> 0
B24: PE | F24: 3 | K24: 1 | M24: 4 | O24: =SUM(C24:N24) -> 8
B25: BA | F25: 4 | G25: 2 | K25: 2 | M25: 2 | O25: =SUM(C25:N25) -> 10
B26: ES | O26: =SUM(C26:N26) -> 0
B27: RJ | F27: 1 | O27: =SUM(C27:N27) -> 1
B28: SP | F28: 17 | G28: 16 | H28: 2 | O28: =SUM(C28:N28) -> 35
B29: PR | O29: =SUM(C29:N29) -> 0
B30: SC | F30: 7 | G30: 9 | O30: =SUM(C30:N30) -> 16
B31: RS | F31: 1 | G31: 1 | O31: =SUM(C31:N31) -> 2
B32: Total Destino | C32: =SUM(C20:C31) -> 0 | D32: =SUM(D20:D31) -> 0 | E32: =SUM(E20:E31) -> 0 | F32: =SUM(F20:F31) -> 33 | G32: =SUM(G20:G31) -> 29 | H32: =SUM(H20:H31) -> 4 | I32: =SUM(I20:I31) -> 0 | J32: =SUM(J20:J31) -> 0 | ... O32: =SUM(O20:O31) -> 75
B34: Movimentação de Contêineres na Cabotagem em 2022 - 40HC
B35: Origem/Destino | C35: AM | D35: PA | E35: MA | F35: CE | G35: PE | H35: BA | I35: ES | J35: RJ | K35: SP | L35: PR | M35: SC | N35: RS | O35: Total Origem
B36: AM | E36: 9 | F36: 6066 | G36: 8232 | H36: 3166 | J36: 7014 | K36: 54983 | L36: 3 | M36: 5501 | N36: 699 | O36: =SUM(C36:N36) -> 85673
B37: PA | F37: 1805 | H37: 4 | K37: 704 | M37: 92 | N37: 6 | O37: =SUM(C37:N37) -> 2611
B38: MA | F38: 51 | K38: 52 | N38: 3 | O38: =SUM(C38:N38) -> 106
B39: CE | C39: 10303 | D39: 985 | E39: 157 | G39: 2481 | H39: 101 | J39: 462 | K39: 7856 | M39: 3188 | N39: 366 | O39: =SUM(C39:N39) -> 25899
B40: PE | C40: 17515 | E40: 405 | F40: 5046 | H40: 652 | I40: 103 | J40: 1554 | K40: 9764 | M40: 4287 | N40: 963 | O40: =SUM(C40:N40) -> 40289
B41: BA | C41: 3252 | E41: 82 | F41: 2029 | G41: 1364 | I41: 58 | J41: 1612 | K41: 10648 | L41: 100 | M41: 2531 | N41: 490 | O41: =SUM(C41:N41) -> 22166
B42: ES | C42: 933 | G42: 11 | O42: =SUM(C42:N42) -> 944
B43: RJ | C43: 3272 | E43: 10 | F43: 1358 | G43: 5765 | H43: 3757 | O43: =SUM(C43:N43) -> 14162
...

Sheet OTIMIZAÇÃO ROTA
B2: ANUAL | K2: SEMANAL | T2: OTIMIZAÇÃO SEMANAL
B4: Movimentação de Contêineres na Cabotagem em 2022 - 20DC | K4: Movimentação de Contêineres na Cabotagem em 2022 - 20DC | T4: Movimentação de Contêineres na Cabotagem em 2022 - 20DC | AC4: Imbalance 20DC
B5: Origem/Destino | C5: AM | D5: CE | E5: PE | F5: BA | G5: SP | H5: SC | I5: Total Origem | K5: Origem/Destino | L5: AM | M5: CE | N5: PE | O5: BA | P5: BA | Q5: SC | R5: Total Origem | T5: Origem/Destino | U5: AM | V5: CE | W5: PE | X5: BA | Y5: BA | Z5: SC | AA5: Total Origem | AC5: Porto | AD5: IMB
B6: AM | D6: 1747 | E6: 313 | F6: 329 | G6: 2513 | H6: 475 | I6: =SUM(C6:H6) -> 5377 | K6: AM | L6: =INT(C6/52) -> 0 | M6: =INT(D6/52) -> 33 | N6: =INT(E6/52) -> 6 | O6: =INT(F6/52) -> 6 | P6: =INT(G6/52) -> 48 | Q6: =INT(H6/52) -> 9 | R6: =SUM(L6:Q6) -> 102 | T6: AM | U6: =L6*C108 -> 0 | V6: =M6*D108 -> 0 | W6: =N6*E108 -> 0.81895122 | X6: =O6*F108 -> 2.7849436 | Y6: =P6*G108 -> 44.217729 | Z6: =Q6*H108 -> 9 | AA6: =SUM(U6:Z6) -> 56.821623 | AC6: AM | AD6: =U12-$AA6 -> 37.958645 | AE6: =INT(ABS(AD6)) -> 37
B7: CE | C7: 2926 | E7: 282 | F7: 491 | G7: 9135 | H7: 4055 | I7: =SUM(C7:H7) -> 16889 | K7: CE | L7: =INT(C7/52) -> 56 | M7: =INT(D7/52) -> 0 | N7: =INT(E7/52) -> 5 | O7: =INT(F7/52) -> 9 | P7: =INT(G7/52) -> 175 | Q7: =INT(H7/52) -> 77 | R7: =SUM(L7:Q7) -> 322 | T7: CE | U7: =L7*C109 -> 55.93375 | V7: =M7*D109 -> 0 | W7: =N7*E109 -> 0.043691546 | X7: =O7*F109 -> 0.61850281 | Y7: =P7*G109 -> 60.251994 | Z7: =Q7*H109 -> 8.4569942 | AA7: =SUM(U7:Z7) -> 125.30493 | AC7: CE | AD7: =V12-$AA7 -> 50.574646 | AE7: =INT(ABS(AD7)) -> 50
B8: PE | C8: 2039 | D8: 1481 | F8: 2967 | G8: 8519 | H8: 827 | I8: =SUM(C8:H8) -> 15833 | K8: PE | L8: =INT(C8/52) -> 39 | M8: =INT(D8/52) -> 28 | N8: =INT(E8/52) -> 0 | O8: =INT(F8/52) -> 57 | P8: =INT(G8/52) -> 163 | Q8: =INT(H8/52) -> 15 | R8: =SUM(L8:Q8) -> 302 | T8: PE | U8: =L8*C110 -> 20.577729 | V8: =M8*D110 -> 15.484659 | W8: =N8*E110 -> 0 | X8: =O8*F110 -> 0.15833686 | Y8: =P8*G110 -> 11.965206 | Z8: =Q8*H110 -> 5.6074985 | AA8: =SUM(U8:Z8) -> 53.793429 | AC8: PE | AD8: =W12-$AA8 -> 92.156857 | AE8: =INT(ABS(AD8)) -> 92
B9: BA | C9: 407 | D9: 779 | E9: 670 | G9: 10907 | H9: 289 | I9: =SUM(C9:H9) -> 13052 | K9: BA | L9: =INT(C9/52) -> 7 | M9: =INT(D9/52) -> 14 | N9: =INT(E9/52) -> 12 | O9: =INT(F9/52) -> 0 | P9: =INT(G9/52) -> 209 | Q9: =INT(H9/52) -> 5 | R9: =SUM(L9:Q9) -> 247 | T9: BA | U9: =L9*C111 -> 3.2302311 | V9: =M9*D111 -> 12.869471 | W9: =N9*E111 -> 11.532832 | X9: =O9*F111 -> 0 | Y9: =P9*G111 -> 0.37267313 | Z9: =Q9*H111 -> 1.4489955 | AA9: =SUM(U9:Z9) -> 29.454203 | AC9: BA | AD9: =X12-$AA9 -> 31.832372 | AE9: =INT(ABS(AD9)) -> 31
B10: SP | C10: 4058 | D10: 6369 | E10: 6570 | F10: 2077 | I10: =SUM(C10:H10) -> 19074 | K10: SP | L10: =INT(C10/52) -> 78 | M10: =INT(D10/52) -> 122 | N10: =INT(E10/52) -> 126 | O10: =INT(F10/52) -> 39 | P10: =INT(G10/52) -> 0 | Q10: =INT(H10/52) -> 0 | R10: =SUM(L10:Q10) -> 365 | T10: SP | U10: =L10*C112 -> 9.9234402 | V10: =M10*D112 -> 39.644032 | W10: =N10*E112 -> 40.220281 | X10: =O10*F112 -> 29.406625 | Y10: =P10*G112 -> 0 | Z10: =Q10*H112 -> 0 | AA10: =SUM(U10:Z10) -> 119.19438 | AC10: SP | AD10: =Y12-$AA10 -> -2.3867767 | AE10: =INT(ABS(AD10)) -> 2
B11: SC | C11: 1452 | D11: 11836 | E11: 13601 | F11: 4203 | I11: =SUM(C11:H11) -> 31092 | K11: SC | L11: =INT(C11/52) -> 27 | M11: =INT(D11/52) -> 227 | N11: =INT(E11/52) -> 261 | O11: =INT(F11/52) -> 80 | P11: =INT(G11/52) -> 0 | Q11: =INT(H11/52) -> 0 | R11: =SUM(L11:Q11) -> 595 | T11: SC | U11: =L11*C113 -> 5.1151187 | V11: =M11*D113 -> 107.88142 | W11: =N11*E113 -> 93.33453 | X11: =O11*F113 -> 28.318167 | Y11: =P11*G113 -> 0 | Z11: =Q11*H113 -> 0 | AA11: =SUM(U11:Z11) -> 234.64923 | AC11: SC | AD11: =Z12-$AA11 -> -210.13574 | AE11: =INT(ABS(AD11)) -> 210
B12: Total Destino | C12: =SUM(C6:C11) -> 10882 | D12: =SUM(D6:D11) -> 22212 | E12: =SUM(E6:E11) -> 21436 | F12: =SUM(F6:F11) -> 10067 | G12: =SUM(G6:G11) -> 31074 | H12: =SUM(H6:H11) -> 5646 | I12: =SUM(I6:I11) -> 101317 | K12: Total Destino | L12: =SUM(L6:L11) -> 207 | M12: =SUM(M6:M11) -> 424 | N12: =SUM(N6:N11) -> 410 | O12: =SUM(O6:O11) -> 191 | P12: =SUM(P6:P11) -> 595 | Q12: =SUM(Q6:Q11) -> 106 | R12: =SUM(R6:R11) -> 1933 | T12: Total Destino | U12: =SUM(U6:U11) -> 94.780269 | V12: =SUM(V6:V11) -> 175.87958 | W12: =SUM(W6:W11) -> 145.95029 | X12: =SUM(X6:X11) -> 61.286575 | Y12: =SUM(Y6:Y11) -> 116.8076 | Z12: =SUM(Z6:Z11) -> 24.513488 | AA12: =SUM(AA6:AA11) -> 619.2178 | AC12: Total | AD12: =SUM(AD6:AD11) -> 0
B14: Movimentação de Contêineres na Cabotagem em 2022 - 20RF | K14: Movimentação de Contêineres na Cabotagem em 2022 - 20RF | T14: Movimentação de Contêineres na Cabotagem em 2022 - 20RF | AC14: Imbalance 20RF
B15: Origem/Destino | C15: AM | D15: CE | E15: PE | F15: BA | G15: SP | H15: SC | I15: Total Origem | K15: Origem/Destino | L15: AM | M15: CE | N15: PE | O15: BA | P15: SP | Q15: SC | R15: Total Origem | T15: Origem/Destino | U15: AM | V15: CE | W15: PE | X15: BA | Y15: SP | Z15: SC | AA15: Total Origem | AC15: Porto | AD15: IMB
B16: AM | E16: 1 | F16: 2 | I16: =SUM(C16:H16) -> 3 | K16: AM | L16: =C16/52 -> 0 | M16: =D16/52 -> 0 | N16: =E16/52 -> 0.019230769 | O16: =F16/52 -> 0.038461538 | P16: =G16/52 -> 0 | Q16: =H16/52 -> 0 | R16: =SUM(L16:Q16) -> 0.057692308 | T16: AM | U16: =L16*C108 -> 0 | V16: =M16*D108 -> 0 | W16: =N16*E108 -> 0.0026248436 | X16: =O16*F108 -> 0.017852202 | Y16: =P16*G108 -> 0 | Z16: =Q16*H108 -> 0 | AA16: =SUM(U16:Z16) -> 0.020477046 | AC16: AM | AD16: =U22-$AA16 -> -0.020477046
B17: CE | I17: =SUM(C17:H17) -> 0 | K17: CE | L17: =C17/52 -> 0 | M17: =D17/52 -> 0 | N17: =E17/52 -> 0 | O17: =F17/52 -> 0 | P17: =G17/52 -> 0 | Q17: =H17/52 -> 0 | R17: =SUM(L17:Q17) -> 0 | T17: CE | U17: =L17*C109 -> 0 | V17: =M17*D109 -> 0 | W17: =N17*E109 -> 0 | X17: =O17*F109 -> 0 | Y17: =P17*G109 -> 0 | Z17: =Q17*H109 -> 0 | AA17: =SUM(U17:Z17) -> 0 | AC17: CE | AD17: =V22-$AA17 -> 0.27282636
B18: PE | D18: 3 | G18: 1 | H18: 4 | I18: =SUM(C18:H18) -> 8 | K18: PE | L18: =C18/52 -> 0 | M18: =D18/52 -> 0.057692308 | N18: =E18/52 -> 0 | O18: =F18/52 -> 0 | P18: =G18/52 -> 0.019230769 | Q18: =H18/52 -> 0.076923077 | R18: =SUM(L18:Q18) -> 0.15384615 | T18: PE | U18: =L18*C110 -> 0 | V18: =M18*D110 -> 0.031905204 | W18: =N18*E110 -> 0 | X18: =O18*F110 -> 0 | Y18: =P18*G110 -> 0.0014116572 | Z18: =Q18*H110 -> 0.028756403 | AA18: =SUM(U18:Z18) -> 0.062073264 | AC18: PE | AD18: =W22-$AA18 -> 0.13762674
B19: RJ | D19: 4 | E19: 2 | G19: 2 | H19: 2 | I19: =SUM(C19:H19) -> 10 | K19: BA | L19: =C19/52 -> 0 | M19: =D19/52 -> 0.076923077 | N19: =E19/52 -> 0.038461538 | O19: =F19/52 -> 0 | P19: =G19/52 -> 0.038461538 | Q19: =H19/52 -> 0.038461538 | R19: =SUM(L19:Q19) -> 0.19230769 | T19: BA | U19: =L19*C111 -> 0 | V19: =M19*D111 -> 0.070711381 | W19: =N19*E111 -> 0.036964205 | X19: =O19*F111 -> 0 | Y19: =P19*G111 -> 6.8581732e-05 | Z19: =Q19*H111 -> 0.01114612 | AA19: =SUM(U19:Z19) -> 0.11889029 | AC19: BA | AD19: =X22-$AA19 -> -0.072037469
B20: SP | D20: 17 | E20: 16 | F20: 2 | I20: =SUM(C20:H20) -> 35 | K20: SP | L20: =C20/52 -> 0 | M20: =D20/52 -> 0.32692308 | N20: =E20/52 -> 0.30769231 | O20: =F20/52 -> 0.038461538 | P20: =G20/52 -> 0 | Q20: =H20/52 -> 0 | R20: =SUM(L20:Q20) -> 0.67307692 | T20: SP | U20: =L20*C112 -> 0 | V20: =M20*D112 -> 0.10623401 | W20: =N20*E112 -> 0.098218025 | X20: =O20*F112 -> 0.029000616 | Y20: =P20*G112 -> 0 | Z20: =Q20*H112 -> 0 | AA20: =SUM(U20:Z20) -> 0.23345265 | AC20: SP | AD20: =Y22-$AA20 -> -0.23197241
B21: SC | D21: 7 | E21: 9 | I21: =SUM(C21:H21) -> 16 | K21: SC | L21: =C21/52 -> 0 | M21: =D21/52 -> 0.13461538 | N21: =E21/52 -> 0.17307692 | O21: =F21/52 -> 0 | P21: =G21/52 -> 0 | Q21: =H21/52 -> 0 | R21: =SUM(L21:Q21) -> 0.30769231 | T21: SC | U21: =L21*C113 -> 0 | V21: =M21*D113 -> 0.063975764 | W21: =N21*E113 -> 0.061892925 | X21: =O21*F113 -> 0 | Y21: =P21*G113 -> 0 | Z21: =Q21*H113 -> 0 | AA21: =SUM(U21:Z21) -> 0.12586869 | AC21: SC | AD21: =Z22-$AA21 -> -0.085966166
B22: Total Destino | C22: =SUM(C16:C21) -> 0 | D22: =SUM(D16:D21) -> 31 | E22: =SUM(E16:E21) -> 28 | F22: =SUM(F16:F21) -> 4 | G22: =SUM(G16:G21) -> 3 | H22: =SUM(H16:H21) -> 6 | I22: =SUM(I16:I21) -> 72 | K22: Total Destino | L22: =SUM(L16:L21) -> 0 | M22: =SUM(M16:M21) -> 0.59615385 | N22: =SUM(N16:N21) -> 0.53846154 | O22: =SUM(O16:O21) -> 0.076923077 | P22: =SUM(P16:P21) -> 0.057692308 | Q22: =SUM(Q16:Q21) -> 0.11538462 | R22: =SUM(R16:R21) -> 1.3846154 | T22: Total Destino | U22: =SUM(U16:U21) -> 0 | V22: =SUM(V16:V21) -> 0.27282636 | W22: =SUM(W16:W21) -> 0.1997 | X22: =SUM(X16:X21) -> 0.046852819 | Y22: =SUM(Y16:Y21) -> 0.0014802389 | Z22: =SUM(Z16:Z21) -> 0.039902522 | AA22: =SUM(AA16:AA21) -> 0.56076193 | AC22: Total | AD22: =SUM(AD16:AD21) -> 0
B24: Movimentação de Contêineres na Cabotagem em 2022 - 40HC | K24: Movimentação de Contêineres na Cabotagem em 2022 - 40HC | T24: Movimentação de Contêineres na Cabotagem em 2022 - 40HC | AC24: Imbalance 40HC
B25: Origem/Destino | C25: AM | D25: CE | E25: PE | F25: BA | G25: SP | H25: SC | I25: Total Origem | K25: Origem/Destino | L25: AM | M25: CE | N25: PE | O25: BA | P25: SP | Q25: SC | R25: Total Origem | T25: Origem/Destino | U25: AM | V25: CE | W25: PE | X25: BA | Y25: SP | Z25: SC | AA25: Total Origem | AC25: Porto | AD25: IMB
B26: AM | D26: 6066 | E26: 8232 | F26: 3166 | G26: 54983 | H26: 5501 | I26: =SUM(C26:H26) -> 77948 | K26: AM | L26: =INT(C26/52) -> 0 | M26: =INT(D26/52) -> 116 | N26: =INT(E26/52) -> 158 | O26: =INT(F26/52) -> 60 | P26: =INT(G26/52) -> 1057 | Q26: =INT(H26/52) -> 105 | R26: =SUM(L26:Q26) -> 1496 | T26: AM | U26: =L26*C108 -> 0 | V26: =M26*D108 -> 0 | W26: =N26*E108 -> 21.565715 | X26: =O26*F108 -> 27.849436 | Y26: =P26*G108 -> 973.71123 | Z26: =Q26*H108 -> 105 | AA26: =SUM(U26:Z26) -> 1128.1264 | AC26: AM | AD26: =U32-$AA26 -> -639.71409 | AE26: =INT(ABS(AD26)) -> 639
B27: CE | C27: 10303 | E27: 2481 | F27: 101 | G27: 7856 | H27: 3188 | I27: =SUM(C27:H27) -> 23929 | K27: CE | L27: =INT(C27/52) -> 198 | M27: =INT(D27/52) -> 0 | N27: =INT(E27/52) -> 47 | O27: =INT(F27/52) -> 1 | P27: =INT(G27/52) -> 151 | Q27: =INT(H27/52) -> 61 | R27: =SUM(L27:Q27) -> 458 | T27: CE | U27: =L27*C109 -> 197.76576 | V27: =M27*D109 -> 0 | W27: =N27*E109 -> 0.41070053 | X27: =O27*F109 -> 0.068722534 | Y27: =P27*G109 -> 51.988863 | Z27: =Q27*H109 -> 6.6996967 | AA27: =SUM(U27:Z27) -> 256.93374 | AC27: CE | AD27: =V32-$AA27 -> 95.451613 | AE27: =INT(ABS(AD27)) -> 95
B28: PE | C28: 17515 | D28: 5046 | F28: 652 | G28: 9764 | H28: 4287 | I28: =SUM(C28:H28) -> 37264 | K28: PE | L28: =INT(C28/52) -> 336 | M28: =INT(D28/52) -> 97 | N28: =INT(E28/52) -> 0 | O28: =INT(F28/52) -> 12 | P28: =INT(G28/52) -> 187 | Q28: =INT(H28/52) -> 82 | R28: =SUM(L28:Q28) -> 714 | T28: PE | U28: =L28*C110 -> 177.28505 | V28: =M28*D110 -> 53.643283 | W28: =N28*E110 -> 0 | X28: =O28*F110 -> 0.033334076 | Y28: =P28*G110 -> 13.726955 | Z28: =Q28*H110 -> 30.654325 | AA28: =SUM(U28:Z28) -> 275.34294 | AC28: PE | AD28: =W32-$AA28 -> 88.693871 | AE28: =INT(ABS(AD28)) -> 88
B29: BA | C29: 3252 | D29: 2029 | E29: 1364 | G29: 10648 | H29: 2531 | I29: =SUM(C29:H29) -> 19824 | K29: BA | L29: =INT(C29/52) -> 62 | M29: =INT(D29/52) -> 39 | N29: =INT(E29/52) -> 26 | O29: =INT(F29/52) -> 0 | P29: =INT(G29/52) -> 204 | Q29: =INT(H29/52) -> 48 | R29: =SUM(L29:Q29) -> 379 | T29: BA | U29: =L29*C111 -> 28.610618 | V29: =M29*D111 -> 35.85067 | W29: =N29*E111 -> 24.987803 | X29: =O29*F111 -> 0 | Y29: =P29*G111 -> 0.36375751 | Z29: =Q29*H111 -> 13.910357 | AA29: =SUM(U29:Z29) -> 103.72321 | AC29: BA | AD29: =X32-$AA29 -> 3.8485788 | AE29: =INT(ABS(AD29)) -> 3
B30: SP | C30: 18041 | D30: 22859 | E30: 29225 | F30: 4383 | I30: =SUM(C30:H30) -> 74508 | K30: SP | L30: =INT(C30/52) -> 346 | M30: =INT(D30/52) -> 439 | N30: =INT(E30/52) -> 562 | O30: =INT(F30/52) -> 84 | P30: =INT(G30/52) -> 0 | Q30: =INT(H30/52) -> 0 | R30: =SUM(L30:Q30) -> 1431 | T30: SP | U30: =L30*C112 -> 44.019363 | V30: =M30*D112 -> 142.65352 | W30: =N30*E112 -> 179.39522 | X30: =O30*F112 -> 63.337346 | Y30: =P30*G112 -> 0 | Z30: =Q30*H112 -> 0 | AA30: =SUM(U30:Z30) -> 429.40546 | AC30: SP | AD30: =Y32-$AA30 -> 610.38535 | AE30: =INT(ABS(AD30)) -> 610
B31: SC | C31: 11210 | D31: 13198 | E31: 20046 | F31: 2406 | I31: =SUM(C31:H31) -> 46860 | K31: SC | L31: =INT(C31/52) -> 215 | M31: =INT(D31/52) -> 253 | N31: =INT(E31/52) -> 385 | O31: =INT(F31/52) -> 46 | P31: =INT(G31/52) -> 0 | Q31: =INT(H31/52) -> 0 | R31: =SUM(L31:Q31) -> 899 | T31: SC | U31: =L31*C113 -> 40.731501 | V31: =M31*D113 -> 120.23788 | W31: =N31*E113 -> 137.67737 | X31: =O31*F113 -> 16.282946 | Y31: =P31*G113 -> 0 | Z31: =Q31*H113 -> 0 | AA31: =SUM(U31:Z31) -> 314.9297 | AC31: SC | AD31: =Z32-$AA31 -> -158.66532 | AE31: =INT(ABS(AD31)) -> 158
B32: Total Destino | C32: =SUM(C26:C31) -> 60321 | D32: =SUM(D26:D31) -> 49198 | E32: =SUM(E26:E31) -> 61348 | F32: =SUM(F26:F31) -> 10708 | G32: =SUM(G26:G31) -> 83251 | H32: =SUM(H26:H31) -> 15507 | I32: =SUM(I26:I31) -> 280333 | K32: Total Destino | L32: =SUM(L26:L31) -> 1157 | M32: =SUM(M26:M31) -> 944 | N32: =SUM(N26:N31) -> 1178 | O32: =SUM(O26:O31) -> 203 | P32: =SUM(P26:P31) -> 1599 | Q32: =SUM(Q26:Q31) -> 296 | R32: =SUM(R26:R31) -> 5377 | T32: Total Destino | U32: =SUM(U26:U31) -> 488.41229 | V32: =SUM(V26:V31) -> 352.38536 | W32: =SUM(W26:W31) -> 364.03681 | X32: =SUM(X26:X31) -> 107.57178 | Y32: =SUM(Y26:Y31) -> 1039.7908 | Z32: =SUM(Z26:Z31) -> 156.26438 | AA32: =SUM(AA26:AA31) -> 2508.4614 | AC32: Total | AD32: =SUM(AD26:AD31) -> 0
B34: Movimentação de Contêineres na Cabotagem em 2022 - 40RH | K34: Movimentação de Contêineres na Cabotagem em 2022 - 40RH | T34: Movimentação de Contêineres na Cabotagem em 2022 - 40RH | AC34: Imbalance 40RH
B35: Origem/Destino | C35: AM | D35: CE | E35: PE | F35: BA | G35: SP | H35: SC | I35: Total Origem | K35: Origem/Destino | L35: AM | M35: CE | N35: PE | O35: BA | P35: SP | Q35: SC | R35: Total Origem | T35: Origem/Destino | U35: AM | V35: CE | W35: PE | X35: BA | Y35: SP | Z35: SC | AA35: Total Origem | AC35: Porto | AD35: IMB
B36: AM | D36: 12 | E36: 6 | F36: 1 | G36: 58 | H36: 46 | I36: =SUM(C36:H36) -> 123 | K36: AM | L36: =INT(C36/52) -> 0 | M36: =INT(D36/52) -> 0 | N36: =INT(E36/52) -> 0 | O36: =INT(F36/52) -> 0 | P36: =INT(G36/52) -> 1 | Q36: =INT(H36/52) -> 0 | R36: =SUM(L36:Q36) -> 1 | T36: AM | U36: =L36*C108 -> 0 | V36: =M36*D108 -> 0 | W36: =N36*E108 -> 0 | X36: =O36*F108 -> 0 | Y36: =P36*G108 -> 0.92120268 | Z36: =Q36*H108 -> 0 | AA36: =SUM(U36:Z36) -> 0.92120268 | AC36: AM | AD36: =U42-$AA36 -> 46.89355 | AE36: =INT(ABS(AD36)) -> 46
B37: CE | C37: 155 | E37: 17 | F37: 2 | G37: 215 | H37: 78 | I37: =SUM(C37:H37) -> 467 | K37: CE | L37: =INT(C37/52) -> 2 | M37: =INT(D37/52) -> 0 | N37: =INT(E37/52) -> 0 | O37: =INT(F37/52) -> 0 | P37: =INT(G37/52) -> 4 | Q37: =INT(H37/52) -> 1 | R37: =SUM(L37:Q37) -> 7 | T37: CE | U37: =L37*C109 -> 1.9976339 | V37: =M37*D109 -> 0 | W37: =N37*E109 -> 0 | X37: =O37*F109 -> 0 | Y37: =P37*G109 -> 1.3771884 | Z37: =Q37*H109 -> 0.10983109 | AA37: =SUM(U37:Z37) -> 3.4846534 | AC37: CE | AD37: =V42-$AA37 -> 51.56625 | AE37: =INT(ABS(AD37)) -> 51
B38: PE | C38: 1593 | D38: 407 | F38: 1 | G38: 40 | H38: 9 | I38: =SUM(C38:H38) -> 2050 | K38: PE | L38: =INT(C38/52) -> 30 | M38: =INT(D38/52) -> 7 | N38: =INT(E38/52) -> 0 | O38: =INT(F38/52) -> 0 | P38: =INT(G38/52) -> 0 | Q38: =INT(H38/52) -> 0 | R38: =SUM(L38:Q38) -> 37 | T38: PE | U38: =L38*C110 -> 15.829022 | V38: =M38*D110 -> 3.8711647 | W38: =N38*E110 -> 0 | X38: =O38*F110 -> 0 | Y38: =P38*G110 -> 0 | Z38: =Q38*H110 -> 0 | AA38: =SUM(U38:Z38) -> 19.700187 | AC38: PE | AD38: =W42-$AA38 -> 34.479744 | AE38: =INT(ABS(AD38)) -> 34
B39: BA | C39: 214 | D39: 327 | E39: 339 | G39: 644 | H39: 24 | I39: =SUM(C39:H39) -> 1548 | K39: BA | L39: =INT(C39/52) -> 4 | M39: =INT(D39/52) -> 6 | N39: =INT(E39/52) -> 6 | O39: =INT(F39/52) -> 0 | P39: =INT(G39/52) -> 12 | Q39: =INT(H39/52) -> 0 | R39: =SUM(L39:Q39) -> 28 | T39: BA | U39: =L39*C111 -> 1.8458463 | V39: =M39*D111 -> 5.5154877 | W39: =N39*E111 -> 5.766416 | X39: =O39*F111 -> 0 | Y39: =P39*G111 -> 0.0213975 | Z39: =Q39*H111 -> 0 | AA39: =SUM(U39:Z39) -> 13.149148 | AC39: BA | AD39: =X42-$AA39 -> -1.1915325 | AE39: =INT(ABS(AD39)) -> 1
B40: SP | C40: 2308 | D40: 2321 | E40: 2268 | F40: 331 | I40: =SUM(C40:H40) -> 7228 | K40: SP | L40: =INT(C40/52) -> 44 | M40: =INT(D40/52) -> 44 | N40: =INT(E40/52) -> 43 | O40: =INT(F40/52) -> 6 | P40: =INT(G40/52) -> 0 | Q40: =INT(H40/52) -> 0 | R40: =SUM(L40:Q40) -> 137 | T40: SP | U40: =L40*C112 -> 5.5978381 | V40: =M40*D112 -> 14.297847 | W40: =N40*E112 -> 13.725969 | X40: =O40*F112 -> 4.5240962 | Y40: =P40*G112 -> 0 | Z40: =Q40*H112 -> 0 | AA40: =SUM(U40:Z40) -> 38.145751 | AC40: SP | AD40: =Y42-$AA40 -> -35.825962 | AE40: =INT(ABS(AD40)) -> 35
B41: SC | C41: 6226 | D41: 3479 | E41: 5045 | F41: 1134 | I41: =SUM(C41:H41) -> 15884 | K41: SC | L41: =INT(C41/52) -> 119 | M41: =INT(D41/52) -> 66 | N41: =INT(E41/52) -> 97 | O41: =INT(F41/52) -> 21 | P41: =INT(G41/52) -> 0 | Q41: =INT(H41/52) -> 0 | R41: =SUM(L41:Q41) -> 303 | T41: SC | U41: =L41*C113 -> 22.544412 | V41: =M41*D113 -> 31.366403 | W41: =N41*E113 -> 34.687546 | X41: =O41*F113 -> 7.4335189 | Y41: =P41*G113 -> 0 | Z41: =Q41*H113 -> 0 | AA41: =SUM(U41:Z41) -> 96.03188 | AC41: SC | AD41: =Z42-$AA41 -> -95.922049 | AE41: =INT(ABS(AD41)) -> 95
B42: Total Destino | C42: =SUM(C36:C41) -> 10496 | D42: =SUM(D36:D41) -> 6546 | E42: =SUM(E36:E41) -> 7675 | F42: =SUM(F36:F41) -> 1469 | G42: =SUM(G36:G41) -> 957 | H42: =SUM(H36:H41) -> 157 | I42: =SUM(I36:I41) -> 27300 | K42: Total Destino | L42: =SUM(L36:L41) -> 199 | M42: =SUM(M36:M41) -> 123 | N42: =SUM(N36:N41) -> 146 | O42: =SUM(O36:O41) -> 27 | P42: =SUM(P36:P41) -> 17 | Q42: =SUM(Q36:Q41) -> 1 | R42: =SUM(R36:R41) -> 513 | T42: Total Destino | U42: =SUM(U36:U41) -> 47.814752 | V42: =SUM(V36:V41) -> 55.050903 | W42: =SUM(W36:W41) -> 54.179931 | X42: =SUM(X36:X41) -> 11.957615 | Y42: =SUM(Y36:Y41) -> 2.3197886 | Z42: =SUM(Z36:Z41) -> 0.10983109 | AA42: =SUM(AA36:AA41) -> 171.43282 | AC42: Total | AD42: =SUM(AD36:AD41) -> 0
B44: Movimentação de Contêineres na Cabotagem em 2022 - unidades | K44: Movimentação de Contêineres na Cabotagem em 2022 - unidades
B45: Origem/Destino | C45: AM | D45: CE | E45: PE | F45: BA | G45: SP | H45: SC | I45: Total Origem | K45: Origem/Destino | L45: AM | M45: CE | N45: PE | O45: BA | P45: SP | Q45: SC | R45: Total Origem
B46: AM | C46: =C6+C16+C26+C36 -> 0 | D46: =D6+D16+D26+D36 -> 7825 | E46: =E6+E16+E26+E36 -> 8552 | F46: =F6+F16+F26+F36 -> 3498 | G46: =G6+G16+G26+G36 -> 57554 | H46: =H6+H16+H26+H36 -> 6022 | I46: =SUM(C46:H46) -> 83451 | K46: AM | L46: =INT(C46/52) -> 0 | M46: =INT(D46/52) -> 150 | N46: =INT(E46/52) -> 164 | O46: =INT(F46/52) -> 67 | P46: =INT(G46/52) -> 1106 | Q46: =INT(H46/52) -> 115 | R46: =SUM(L46:Q46) -> 1602
...

Sheet __Solver__
A1: 2023681688872554185 | D1: t3JImZndu39Hg58 | J1: 1
A2: =MAX('OTIMIZA ROTA'!AY38) -> 65986446
A3: ='OTIMIZA ROTA'!P90:Q90 -> #VALUE!
A4: OGM=
A6: RQJ7el5pX1VGAA==
A7: ='OTIMIZA ROTA'!L68:Q73 <= 'OTIMIZA ROTA'!L6:Q11 -> #VALUE!
A8: ='OTIMIZA ROTA'!L78:Q83 <= 'OTIMIZA ROTA'!L26:Q31 -> #VALUE!
A9: ='OTIMIZA ROTA'!L88:Q93 <= 'OTIMIZA ROTA'!L36:Q41 -> #VALUE!
A10: ='OTIMIZA ROTA'!L68:Q73 <= 0 -> #VALUE!
A11: ='OTIMIZA ROTA'!L78:Q83 <= 0 -> #VALUE!
A12: ='OTIMIZA ROTA'!L88:Q93 <= 0 -> #VALUE!
A13: ='OTIMIZA ROTA'!AF75:AL75 <= 'OTIMIZA ROTA'!AF76:AL76 -> #VALUE!
A14: ='OTIMIZA ROTA'!AO75:AU75 <= 'OTIMIZA ROTA'!AO76:AU76 -> #VALUE!
A15: ='OTIMIZA ROTA'!AO75:AU75 <= 0 -> #VALUE!
A16: ='OTIMIZA ROTA'!AF75:AL75 <= 0 -> #VALUE!

Sheet __Solver___conflict2099073712

Sheet __Solver___conflict325174676

Sheet __Solver___conflict976500911

Sheet __Solver___conflict1703220588

Sheet __Solver___conflict78492872

Sheet __Solver___conflict342278247

Sheet __Solver___conflict1363959748

Sheet __Solver___conflict1329151324

Sheet Copy of OTIMIZAÇÃO ROTA
AC1: DFVV
B2: ANUAL | K2: SEMANAL | T2: SEMANAL VAZIO
B4: Movimentação de Contêineres na Cabotagem em 2022 - 20DC | K4: MATRIZ OD 20 DC CHEIOS | T4: Imbalance 20DC | W4: MATRIZ OD 20 DC VAZIOS | AF4: MATRIZ OD 20 DC CHEIOS - TONELADAS | AO4: MATRIZ OD 20 DC VAZIOS - TONELADAS | AX4: RESUMO SOMA QNTD CONTÊINERS CHEIOS - 20 DC + 40 DC + 40 RH | BG4: RESUMO SOMA QNTD CONTÊINERS VAZIOS - 20 DC + 40 DC + 40 RH
B5: Origem/Destino | C5: AM | D5: CE | E5: PE | F5: BA | G5: SP | H5: SC | I5: Total Origem | K5: Origem/Destino | L5: AM | M5: CE | N5: PE | O5: BA | P5: SP | Q5: SC | R5: Total Origem | T5: Porto | U5: IMB | W5: Origem/Destino | X5: AM | Y5: CE | Z5: PE | AA5: BA | AB5: SP | AC5: SC | AD5: Total Origem | AF5: Origem/Destino | AG5: AM | AH5: CE | AI5: PE | AJ5: BA | AK5: SP | AL5: SC | AM5: Total Origem | AO5: Origem/Destino | AP5: AM | AQ5: CE | AR5: PE | AS5: BA | AT5: SP | AU5: SC | AV5: Total Origem | AX5: Origem/Destino | AY5: AM | AZ5: CE | BA5: PE | BB5: BA | BC5: SP | BD5: SC | BE5: Total Origem | BG5: Origem/Destino | BH5: AM | BI5: CE | BJ5: PE | BK5: BA | BL5: SP | BM5: SC | BN5: Total Origem
B6: AM | D6: 1747 | E6: 313 | F6: 329 | G6: 2513 | H6: 475 | I6: =SUM(C6:H6) -> 5377 | K6: AM | L6: =INT(C6/52) -> 0 | M6: =INT(D6/52) -> 33 | N6: =INT(E6/52) -> 6 | O6: =INT(F6/52) -> 6 | P6: =INT(G6/52) -> 48 | Q6: =INT(H6/52) -> 9 | R6: =SUM(L6:Q6) -> 102 | T6: AM | U6: =L12-R6 -> 105 | W6: AM | AB6: 56 | AC6: 49 | AD6: =SUM(X6:AC6) -> 105 | AF6: AM | AG6: =L6*28 -> 0 | AH6: =M6*28 -> 924 | AI6: =N6*28 -> 168 | AJ6: =O6*28 -> 168 | AK6: =P6*28 -> 1344 | AL6: =Q6*28 -> 252 | AM6: =SUM(AG6:AL6) -> 2856 | AO6: AM | AP6: =X6*2 -> 0 | AQ6: =Y6*2 -> 0 | AR6: =Z6*2 -> 0 | AS6: =AA6*2 -> 0 | AT6: =AB6*2 -> 112 | AU6: =AC6*2 -> 98 | AV6: =SUM(AP6:AU6) -> 210 | AX6: AM | AY6: =SUM(L6,L26,L46) -> 0 | AZ6: =SUM(M6,M26,M46) -> 149 | BA6: =SUM(N6,N26,N46) -> 164 | BB6: =SUM(O6,O26,O46) -> 66 | BC6: =SUM(P6,P26,P46) -> 1106 | BD6: =SUM(Q6,Q26,Q46) -> 114 | BE6: =SUM(AY6:BD6) -> 1599 | BG6: AM | BH6: =SUM(X6,X26,X46) -> 0 | BI6: =SUM(Y6,Y26,Y46) -> 0 | BJ6: =SUM(Z6,Z26,Z46) -> 0 | BK6: =SUM(AA6,AA26,AA46) -> 0 | BL6: =SUM(AB6,AB26,AB46) -> 56 | BM6: =SUM(AC6,AC26,AC46) -> 246 | BN6: =SUM(BH6:BM6) -> 302
B7: CE | C7: 2926 | E7: 282 | F7: 491 | G7: 9135 | H7: 4055 | I7: =SUM(C7:H7) -> 16889 | K7: CE | L7: =INT(C7/52) -> 56 | M7: =INT(D7/52) -> 0 | N7: =INT(E7/52) -> 5 | O7: =INT(F7/52) -> 9 | P7: =INT(G7/52) -> 175 | Q7: =INT(H7/52) -> 77 | R7: =SUM(L7:Q7) -> 322 | T7: CE | U7: =M12-R7 -> 102 | W7: CE | AC7: =U7 -> 102 | AD7: =SUM(X7:AC7) -> 102 | AF7: CE | AG7: =L7*28 -> 1568 | AH7: =M7*28 -> 0 | AI7: =N7*28 -> 140 | AJ7: =O7*28 -> 252 | AK7: =P7*28 -> 4900 | AL7: =Q7*28 -> 2156 | AM7: =SUM(AG7:AL7) -> 9016 | AO7: CE | AP7: =X7*2 -> 0 | AQ7: =Y7*2 -> 0 | AR7: =Z7*2 -> 0 | AS7: =AA7*2 -> 0 | AT7: =AB7*2 -> 0 | AU7: =AC7*2 -> 204 | AV7: =SUM(AP7:AU7) -> 204 | AX7: CE | AY7: =SUM(L7,L27,L47) -> 256 | AZ7: =SUM(M7,M27,M47) -> 0 | BA7: =SUM(N7,N27,N47) -> 52 | BB7: =SUM(O7,O27,O47) -> 10 | BC7: =SUM(P7,P27,P47) -> 330 | BD7: =SUM(Q7,Q27,Q47) -> 139 | BE7: =SUM(AY7:BD7) -> 787 | BG7: CE | BH7: =SUM(X7,X27,X47) -> 339 | BI7: =SUM(Y7,Y27,Y47) -> 0 | BJ7: =SUM(Z7,Z27,Z47) -> 0 | BK7: =SUM(AA7,AA27,AA47) -> 0 | BL7: =SUM(AB7,AB27,AB47) -> 11 | BM7: =SUM(AC7,AC27,AC47) -> 354 | BN7: =SUM(BH7:BM7) -> 704
B8: PE | C8: 2039 | D8: 1481 | F8: 2967 | G8: 8519 | H8: 827 | I8: =SUM(C8:H8) -> 15833 | K8: PE | L8: =INT(C8/52) -> 39 | M8: =INT(D8/52) -> 28 | N8: =INT(E8/52) -> 0 | O8: =INT(F8/52) -> 57 | P8: =INT(G8/52) -> 163 | Q8: =INT(H8/52) -> 15 | R8: =SUM(L8:Q8) -> 302 | T8: PE | U8: =N12-R8 -> 108 | W8: PE | AC8: =U8 -> 108 | AD8: =SUM(X8:AC8) -> 108 | AF8: PE | AG8: =L8*28 -> 1092 | AH8: =M8*28 -> 784 | AI8: =N8*28 -> 0 | AJ8: =O8*28 -> 1596 | AK8: =P8*28 -> 4564 | AL8: =Q8*28 -> 420 | AM8: =SUM(AG8:AL8) -> 8456 | AO8: PE | AP8: =X8*2 -> 0 | AQ8: =Y8*2 -> 0 | AR8: =Z8*2 -> 0 | AS8: =AA8*2 -> 0 | AT8: =AB8*2 -> 0 | AU8: =AC8*2 -> 216 | AV8: =SUM(AP8:AU8) -> 216 | AX8: PE | AY8: =SUM(L8,L28,L48) -> 405 | AZ8: =SUM(M8,M28,M48) -> 132 | BA8: =SUM(N8,N28,N48) -> 0 | BB8: =SUM(O8,O28,O48) -> 69 | BC8: =SUM(P8,P28,P48) -> 350 | BD8: =SUM(Q8,Q28,Q48) -> 97 | BE8: =SUM(AY8:BD8) -> 1053 | BG8: PE | BH8: =SUM(X8,X28,X48) -> 0 | BI8: =SUM(Y8,Y28,Y48) -> 0 | BJ8: =SUM(Z8,Z28,Z48) -> 0 | BK8: =SUM(AA8,AA28,AA48) -> 1 | BL8: =SUM(AB8,AB28,AB48) -> 285 | BM8: =SUM(AC8,AC28,AC48) -> 396 | BN8: =SUM(BH8:BM8) -> 682
B9: BA | C9: 407 | D9: 779 | E9: 670 | G9: 10907 | H9: 289 | I9: =SUM(C9:H9) -> 13052 | K9: BA | L9: =INT(C9/52) -> 7 | M9: =INT(D9/52) -> 14 | N9: =INT(E9/52) -> 12 | O9: =INT(F9/52) -> 0 | P9: =INT(G9/52) -> 209 | Q9: =INT(H9/52) -> 5 | R9: =SUM(L9:Q9) -> 247 | T9: BA | U9: =O12-R9 -> -56 | W9: BA | AD9: =SUM(X9:AC9) -> 0 | AF9: BA | AG9: =L9*28 -> 196 | AH9: =M9*28 -> 392 | AI9: =N9*28 -> 336 | AJ9: =O9*28 -> 0 | AK9: =P9*28 -> 5852 | AL9: =Q9*28 -> 140 | AM9: =SUM(AG9:AL9) -> 6916 | AO9: BA | AP9: =X9*2 -> 0 | AQ9: =Y9*2 -> 0 | AR9: =Z9*2 -> 0 | AS9: =AA9*2 -> 0 | AT9: =AB9*2 -> 0 | AU9: =AC9*2 -> 0 | AV9: =SUM(AP9:AU9) -> 0 | AX9: BA | AY9: =SUM(L9,L29,L49) -> 73 | AZ9: =SUM(M9,M29,M49) -> 59 | BA9: =SUM(N9,N29,N49) -> 44 | BB9: =SUM(O9,O29,O49) -> 0 | BC9: =SUM(P9,P29,P49) -> 425 | BD9: =SUM(Q9,Q29,Q49) -> 53 | BE9: =SUM(AY9:BD9) -> 654 | BG9: BA | BH9: =SUM(X9,X29,X49) -> 0 | BI9: =SUM(Y9,Y29,Y49) -> 0 | BJ9: =SUM(Z9,Z29,Z49) -> 0 | BK9: =SUM(AA9,AA29,AA49) -> 0 | BL9: =SUM(AB9,AB29,AB49) -> 0 | BM9: =SUM(AC9,AC29,AC49) -> 0 | BN9: =SUM(BH9:BM9) -> 0
B10: SP | C10: 4058 | D10: 6369 | E10: 6570 | F10: 2077 | I10: =SUM(C10:H10) -> 19074 | K10: SP | L10: =INT(C10/52) -> 78 | M10: =INT(D10/52) -> 122 | N10: =INT(E10/52) -> 126 | O10: =INT(F10/52) -> 39 | P10: =INT(G10/52) -> 0 | Q10: =INT(H10/52) -> 0 | R10: =SUM(L10:Q10) -> 365 | T10: SP | U10: =P12-R10 -> 230 | W10: SP | AC10: =U10 -> 230 | AD10: =SUM(X10:AC10) -> 230 | AF10: SP | AG10: =L10*28 -> 2184 | AH10: =M10*28 -> 3416 | AI10: =N10*28 -> 3528 | AJ10: =O10*28 -> 1092 | AK10: =P10*28 -> 0 | AL10: =Q10*28 -> 0 | AM10: =SUM(AG10:AL10) -> 10220 | AO10: SP | AP10: =X10*2 -> 0 | AQ10: =Y10*2 -> 0 | AR10: =Z10*2 -> 0 | AS10: =AA10*2 -> 0 | AT10: =AB10*2 -> 0 | AU10: =AC10*2 -> 460 | AV10: =SUM(AP10:AU10) -> 460 | AX10: SP | AY10: =SUM(L10,L30,L50) -> 468 | AZ10: =SUM(M10,M30,M50) -> 605 | BA10: =SUM(N10,N30,N50) -> 731 | BB10: =SUM(O10,O30,O50) -> 129 | BC10: =SUM(P10,P30,P50) -> 0 | BD10: =SUM(Q10,Q30,Q50) -> 0 | BE10: =SUM(AY10:BD10) -> 1933 | BG10: SP | BH10: =SUM(X10,X30,X50) -> 0 | BI10: =SUM(Y10,Y30,Y50) -> 0 | BJ10: =SUM(Z10,Z30,Z50) -> 0 | BK10: =SUM(AA10,AA30,AA50) -> 0 | BL10: =SUM(AB10,AB30,AB50) -> 0 | BM10: =SUM(AC10,AC30,AC50) -> 398 | BN10: =SUM(BH10:BM10) -> 398
B11: SC | C11: 1452 | D11: 11836 | E11: 13601 | F11: 4203 | I11: =SUM(C11:H11) -> 31092 | K11: SC | L11: =INT(C11/52) -> 27 | M11: =INT(D11/52) -> 227 | N11: =INT(E11/52) -> 261 | O11: =INT(F11/52) -> 80 | P11: =INT(G11/52) -> 0 | Q11: =INT(H11/52) -> 0 | R11: =SUM(L11:Q11) -> 595 | T11: SC | U11: =Q12-R11 -> -489 | W11: SC | AD11: =SUM(X11:AC11) -> 0 | AF11: SC | AG11: =L11*28 -> 756 | AH11: =M11*28 -> 6356 | AI11: =N11*28 -> 7308 | AJ11: =O11*28 -> 2240 | AK11: =P11*28 -> 0 | AL11: =Q11*28 -> 0 | AM11: =SUM(AG11:AL11) -> 16660 | AO11: SC | AP11: =X11*2 -> 0 | AQ11: =Y11*2 -> 0 | AR11: =Z11*2 -> 0 | AS11: =AA11*2 -> 0 | AT11: =AB11*2 -> 0 | AU11: =AC11*2 -> 0 | AV11: =SUM(AP11:AU11) -> 0 | AX11: SC | AY11: =SUM(L11,L31,L51) -> 361 | AZ11: =SUM(M11,M31,M51) -> 546 | BA11: =SUM(N11,N31,N51) -> 743 | BB11: =SUM(O11,O31,O51) -> 147 | BC11: =SUM(P11,P31,P51) -> 0 | BD11: =SUM(Q11,Q31,Q51) -> 0 | BE11: =SUM(AY11:BD11) -> 1797 | BG11: SC | BH11: =SUM(X11,X31,X51) -> 0 | BI11: =SUM(Y11,Y31,Y51) -> 0 | BJ11: =SUM(Z11,Z31,Z51) -> 0 | BK11: =SUM(AA11,AA31,AA51) -> 0 | BL11: =SUM(AB11,AB31,AB51) -> 0 | BM11: =SUM(AC11,AC31,AC51) -> 0 | BN11: =SUM(BH11:BM11) -> 0
B12: Total Destino | C12: =SUM(C6:C11) -> 10882 | D12: =SUM(D6:D11) -> 22212 | E12: =SUM(E6:E11) -> 21436 | F12: =SUM(F6:F11) -> 10067 | G12: =SUM(G6:G11) -> 31074 | H12: =SUM(H6:H11) -> 5646 | I12: =SUM(I6:I11) -> 101317 | K12: Total Destino | L12: =SUM(L6:L11) -> 207 | M12: =SUM(M6:M11) -> 424 | N12: =SUM(N6:N11) -> 410 | O12: =SUM(O6:O11) -> 191 | P12: =SUM(P6:P11) -> 595 | Q12: =SUM(Q6:Q11) -> 106 | R12: =SUM(R6:R11) -> 1933 | T12: Total | U12: =SUM(U6:U11) -> 0 | W12: Total Destino | X12: =SUM(X6:X11) -> 0 | Y12: =SUM(Y6:Y11) -> 0 | Z12: =SUM(Z6:Z11) -> 0 | AA12: =SUM(AA6:AA11) -> 0 | AB12: =SUM(AB6:AB11) -> 56 | AC12: =SUM(AC6:AC11) -> 489 | AD12: =SUM(AD6:AD11) -> 545 | AF12: Total Destino | AG12: =SUM(AG6:AG11) -> 5796 | AH12: =SUM(AH6:AH11) -> 11872 | AI12: =SUM(AI6:AI11) -> 11480 | AJ12: =SUM(AJ6:AJ11) -> 5348 | AK12: =SUM(AK6:AK11) -> 16660 | AL12: =SUM(AL6:AL11) -> 2968 | AM12: 1933 | AO12: Total Destino | AP12: =SUM(AP6:AP11) -> 0 | AQ12: =SUM(AQ6:AQ11) -> 0 | AR12: =SUM(AR6:AR11) -> 0 | AS12: =SUM(AS6:AS11) -> 0 | AT12: =SUM(AT6:AT11) -> 112 | AU12: =SUM(AU6:AU11) -> 978 | AV12: =SUM(AV6:AV11) -> 1090 | AX12: Total Destino | AY12: =SUM(AY6:AY11) -> 1563 | AZ12: =SUM(AZ6:AZ11) -> 1491 | BA12: =SUM(BA6:BA11) -> 1734 | BB12: =SUM(BB6:BB11) -> 421 | BC12: =SUM(BC6:BC11) -> 2211 | BD12: =SUM(BD6:BD11) -> 403 | BE12: =SUM(BE6:BE11) -> 7823 | BG12: Total Destino | BH12: =SUM(BH6:BH11) -> 339 | BI12: =SUM(BI6:BI11) -> 0 | BJ12: =SUM(BJ6:BJ11) -> 0 | BK12: =SUM(BK6:BK11) -> 1 | BL12: =SUM(BL6:BL11) -> 352 | BM12: =SUM(BM6:BM11) -> 1394 | BN12: =SUM(BN6:BN11) -> 2086
B14: Movimentação de Contêineres na Cabotagem em 2022 - 20RF | K14: MATRIZ OD CALCULADA SOLVER 20 DC CHEIO | T14: RECEITA POTENCIAL CABOTAGEM SEMANAL 20 DC | AX14: RESUMO SOMA - CONTEINERS CHEIOS (ton) | BG14: RESUMO SOMA - CONTEINERS VAZIOS (ton)
B15: Origem/Destino | C15: AM | D15: CE | E15: PE | F15: BA | G15: SP | H15: SC | I15: Total Origem | K15: Origem/Destino | L15: AM | M15: CE | N15: PE | O15: BA | P15: SP | Q15: SC | R15: Total Origem | T15: Origem/Destino | U15: AM | V15: CE | W15: PE | X15: BA | Y15: SP | Z15: SC | AX15: Origem/Destino | AY15: AM | AZ15: CE | BA15: PE | BB15: BA | BC15: SP | BD15: SC | BE15: Total Origem | BG15: Origem/Destino | BH15: AM | BI15: CE | BJ15: PE | BK15: BA | BL15: SP | BM15: SC | BN15: Total Origem
B16: AM | E16: 1 | F16: 2 | I16: =SUM(C16:H16) -> 3 | K16: AM | L16: =INT(C16/52) -> 0 | M16: =INT(D16/52) -> 0 | N16: =INT(E16/52) -> 0 | O16: =INT(F16/52) -> 0 | P16: =INT(G16/52) -> 0 | Q16: =INT(H16/52) -> 0 | R16: =SUM(L16:Q16) -> 0 | T16: AM | U16: =L6*C76 -> 0 | V16: =M6*D76 -> #NAME? | W16: =N6*E76 -> #NAME? | X16: =O6*F76 -> #NAME? | Y16: =P6*G76 -> #NAME? | Z16: =Q6*H76 -> #NAME? | AX16: AM | AY16: =SUM(AG6,AG26,AG46) -> 0 | AZ16: =SUM(AH6,AH26,AH46) -> 4172 | BA16: =SUM(AI6,AI26,AI46) -> 4592 | BB16: =SUM(AJ6,AJ26,AJ46) -> 1848 | BC16: =SUM(AK6,AK26,AK46) -> 30968 | BD16: =SUM(AL6,AL26,AL46) -> 3192 | BE16: =SUM(AY16:BD16) -> 44772 | BG16: AM | BH16: =SUM(AP6,AP26,AP46) -> 0 | BI16: =SUM(AQ6,AQ26,AQ46) -> 0 | BJ16: =SUM(AR6,AR26,AR46) -> 0 | BK16: =SUM(AS6,AS26,AS46) -> 0 | BL16: =SUM(AT6,AT26,AT46) -> 112 | BM16: =SUM(AU6,AU26,AU46) -> 886 | BN16: =SUM(BH16:BM16) -> 998
B17: CE | I17: =SUM(C17:H17) -> 0 | K17: CE | L17: =INT(C17/52) -> 0 | M17: =INT(D17/52) -> 0 | N17: =INT(E17/52) -> 0 | O17: =INT(F17/52) -> 0 | P17: =INT(G17/52) -> 0 | Q17: =INT(H17/52) -> 0 | R17: =SUM(L17:Q17) -> 0 | T17: CE | U17: =L7*C77 -> #NAME? | V17: =M7*D77 -> 0 | W17: =N7*E77 -> #NAME? | X17: =O7*F77 -> #NAME? | Y17: =P7*G77 -> #NAME? | Z17: =Q7*H77 -> #NAME? | AX17: CE | AY17: =SUM(AG7,AG27,AG47) -> 7168 | AZ17: =SUM(AH7,AH27,AH47) -> 0 | BA17: =SUM(AI7,AI27,AI47) -> 1456 | BB17: =SUM(AJ7,AJ27,AJ47) -> 280 | BC17: =SUM(AK7,AK27,AK47) -> 9240 | BD17: =SUM(AL7,AL27,AL47) -> 3892 | BE17: =SUM(AY17:BD17) -> 22036 | BG17: CE | BH17: =SUM(AP7,AP27,AP47) -> 1356 | BI17: =SUM(AQ7,AQ27,AQ47) -> 0 | BJ17: =SUM(AR7,AR27,AR47) -> 0 | BK17: =SUM(AS7,AS27,AS47) -> 0 | BL17: =SUM(AT7,AT27,AT47) -> 44 | BM17: =SUM(AU7,AU27,AU47) -> 1212 | BN17: =SUM(BH17:BM17) -> 2612
B18: PE | D18: 3 | G18: 1 | H18: 4 | I18: =SUM(C18:H18) -> 8 | K18: PE | L18: =INT(C18/52) -> 0 | M18: =INT(D18/52) -> 0 | N18: =INT(E18/52) -> 0 | O18: =INT(F18/52) -> 0 | P18: =INT(G18/52) -> 0 | Q18: =INT(H18/52) -> 0 | R18: =SUM(L18:Q18) -> 0 | T18: PE | U18: =L8*C78 -> #NAME? | V18: =M8*D78 -> #NAME? | W18: =N8*E78 -> 0 | X18: =O8*F78 -> #NAME? | Y18: =P8*G78 -> #NAME? | Z18: =Q8*H78 -> #NAME? | AX18: PE | AY18: =SUM(AG8,AG28,AG48) -> 11340 | AZ18: =SUM(AH8,AH28,AH48) -> 3696 | BA18: =SUM(AI8,AI28,AI48) -> 0 | BB18: =SUM(AJ8,AJ28,AJ48) -> 1932 | BC18: =SUM(AK8,AK28,AK48) -> 9800 | BD18: =SUM(AL8,AL28,AL48) -> 2716 | BE18: =SUM(AY18:BD18) -> 29484 | BG18: PE | BH18: =SUM(AP8,AP28,AP48) -> 0 | BI18: =SUM(AQ8,AQ28,AQ48) -> 0 | BJ18: =SUM(AR8,AR28,AR48) -> 0 | BK18: =SUM(AS8,AS28,AS48) -> 4 | BL18: =SUM(AT8,AT28,AT48) -> 1140 | BM18: =SUM(AU8,AU28,AU48) -> 1368 | BN18: =SUM(BH18:BM18) -> 2512
B19: RJ | D19: 4 | E19: 2 | G19: 2 | H19: 2 | I19: =SUM(C19:H19) -> 10 | K19: BA | L19: =INT(C19/52) -> 0 | M19: =INT(D19/52) -> 0 | N19: =INT(E19/52) -> 0 | O19: =INT(F19/52) -> 0 | P19: =INT(G19/52) -> 0 | Q19: =INT(H19/52) -> 0 | R19: =SUM(L19:Q19) -> 0 | T19: BA | U19: =L9*C79 -> #NAME? | V19: =M9*D79 -> #NAME? | W19: =N9*E79 -> #NAME? | X19: =O9*F79 -> 0 | Y19: =P9*G79 -> 0 | Z19: =Q9*H79 -> #NAME? | AX19: BA | AY19: =SUM(AG9,AG29,AG49) -> 2044 | AZ19: =SUM(AH9,AH29,AH49) -> 1652 | BA19: =SUM(AI9,AI29,AI49) -> 1232 | BB19: =SUM(AJ9,AJ29,AJ49) -> 0 | BC19: =SUM(AK9,AK29,AK49) -> 11900 | BD19: =SUM(AL9,AL29,AL49) -> 1484 | BE19: =SUM(AY19:BD19) -> 18312 | BG19: BA | BH19: =SUM(AP9,AP29,AP49) -> 0 | BI19: =SUM(AQ9,AQ29,AQ49) -> 0 | BJ19: =SUM(AR9,AR29,AR49) -> 0 | BK19: =SUM(AS9,AS29,AS49) -> 0 | BL19: =SUM(AT9,AT29,AT49) -> 0 | BM19: =SUM(AU9,AU29,AU49) -> 0 | BN19: =SUM(BH19:BM19) -> 0
B20: SP | D20: 17 | E20: 16 | F20: 2 | I20: =SUM(C20:H20) -> 35 | K20: SP | L20: =INT(C20/52) -> 0 | M20: =INT(D20/52) -> 0 | N20: =INT(E20/52) -> 0 | O20: =INT(F20/52) -> 0 | P20: =INT(G20/52) -> 0 | Q20: =INT(H20/52) -> 0 | R20: =SUM(L20:Q20) -> 0 | T20: SP | U20: =L10*C80 -> #NAME? | V20: =M10*D80 -> #NAME? | W20: =N10*E80 -> #NAME? | X20: =O10*F80 -> #NAME? | Y20: =P10*G80 -> 0 | Z20: =Q10*H80 -> 0 | AX20: SP | AY20: =SUM(AG10,AG30,AG50) -> 13104 | AZ20: =SUM(AH10,AH30,AH50) -> 16940 | BA20: =SUM(AI10,AI30,AI50) -> 20468 | BB20: =SUM(AJ10,AJ30,AJ50) -> 3612 | BC20: =SUM(AK10,AK30,AK50) -> 0 | BD20: =SUM(AL10,AL30,AL50) -> 0 | BE20: =SUM(AY20:BD20) -> 54124 | BG20: SP | BH20: =SUM(AP10,AP30,AP50) -> 0 | BI20: =SUM(AQ10,AQ30,AQ50) -> 0 | BJ20: =SUM(AR10,AR30,AR50) -> 0 | BK20: =SUM(AS10,AS30,AS50) -> 0 | BL20: =SUM(AT10,AT30,AT50) -> 0 | BM20: =SUM(AU10,AU30,AU50) -> 1132 | BN20: =SUM(BH20:BM20) -> 1132
B21: SC | D21: 7 | E21: 9 | I21: =SUM(C21:H21) -> 16 | K21: SC | L21: =INT(C21/52) -> 0 | M21: =INT(D21/52) -> 0 | N21: =INT(E21/52) -> 0 | O21: =INT(F21/52) -> 0 | P21: =INT(G21/52) -> 0 | Q21: =INT(H21/52) -> 0 | R21: =SUM(L21:Q21) -> 0 | T21: SC | U21: =L11*C81 -> #NAME? | V21: =M11*D81 -> #NAME? | W21: =N11*E81 -> #NAME? | X21: =O11*F81 -> #NAME? | Y21: =P11*G81 -> 0 | Z21: =Q11*H81 -> 0 | AX21: SC | AY21: =SUM(AG11,AG31,AG51) -> 10108 | AZ21: =SUM(AH11,AH31,AH51) -> 15288 | BA21: =SUM(AI11,AI31,AI51) -> 20804 | BB21: =SUM(AJ11,AJ31,AJ51) -> 4116 | BC21: =SUM(AK11,AK31,AK51) -> 0 | BD21: =SUM(AL11,AL31,AL51) -> 0 | BE21: =SUM(AY21:BD21) -> 50316 | BG21: SC | BH21: =SUM(AP11,AP31,AP51) -> 0 | BI21: =SUM(AQ11,AQ31,AQ51) -> 0 | BJ21: =SUM(AR11,AR31,AR51) -> 0 | BK21: =SUM(AS11,AS31,AS51) -> 0 | BL21: =SUM(AT11,AT31,AT51) -> 0 | BM21: =SUM(AU11,AU31,AU51) -> 0 | BN21: =SUM(BH21:BM21) -> 0
B22: Total Destino | C22: =SUM(C16:C21) -> 0 | D22: =SUM(D16:D21) -> 31 | E22: =SUM(E16:E21) -> 28 | F22: =SUM(F16:F21) -> 4 | G22: =SUM(G16:G21) -> 3 | H22: =SUM(H16:H21) -> 6 | I22: =SUM(I16:I21) -> 72 | K22: Total Destino | L22: =SUM(L16:L21) -> 0 | M22: =SUM(M16:M21) -> 0 | N22: =SUM(N16:N21) -> 0 | O22: =SUM(O16:O21) -> 0 | P22: =SUM(P16:P21) -> 0 | Q22: =SUM(Q16:Q21) -> 0 | R22: =SUM(R16:R21) -> 0 | Z22: $ RECEITA SEM. | AA22: =SUM(U16:Z21) -> #NAME? | AX22: Total Destino | AY22: =SUM(AY16:AY21) -> 43764 | AZ22: =SUM(AZ16:AZ21) -> 41748 | BA22: =SUM(BA16:BA21) -> 48552 | BB22: =SUM(BB16:BB21) -> 11788 | BC22: =SUM(BC16:BC21) -> 61908 | BD22: =SUM(BD16:BD21) -> 11284 | BE22: =SUM(BE16:BE21) -> 219044 | BG22: Total Destino | BH22: =SUM(BH16:BH21) -> 1356 | BI22: =SUM(BI16:BI21) -> 0 | BJ22: =SUM(BJ16:BJ21) -> 0 | BK22: =SUM(BK16:BK21) -> 4 | BL22: =SUM(BL16:BL21) -> 1296 | BM22: =SUM(BM16:BM21) -> 4598 | BN22: =SUM(BN16:BN21) -> 7254
B24: Movimentação de Contêineres na Cabotagem em 2022 - 40HC | K24: Movimentação de Contêineres na Cabotagem em 2022 - 40HC | T24: Imbalance 40HC | W24: MATRIZ OD 40HC VAZIOS | AF24: MATRIZ OD 40 HC CHEIOS - TONELADAS | AO24: MATRIZ OD 40 HC VAZIOS - TONELADAS | AX24: RESUMO SOMA - CONTEINERS CHEIOS (TEUs) | BG24: RESUMO SOMA - CONTEINERS VAZIOS (TEUs)
B25: Origem/Destino | C25: AM | D25: CE | E25: PE | F25: BA | G25: SP | H25: SC | I25: Total Origem | K25: Origem/Destino | L25: AM | M25: CE | N25: PE | O25: BA | P25: SP | Q25: SC | R25: Total Origem | T25: Porto | U25: IMB | W25: Origem/Destino | X25: AM | Y25: CE | Z25: PE | AA25: BA | AB25: SP | AC25: SC | AD25: Total Origem | AF25: Origem/Destino | AG25: AM | AH25: CE | AI25: PE | AJ25: BA | AK25: SP | AL25: SC | AM25: Total Origem | AO25: Origem/Destino | AP25: AM | AQ25: CE | AR25: PE | AS25: BA | AT25: SP | AU25: SC | AV25: Total Origem | AX25: Origem/Destino | AY25: AM | AZ25: CE | BA25: PE | BB25: BA | BC25: SP | BD25: SC | BE25: Total Origem | BG25: Origem/Destino | BH25: AM | BI25: CE | BJ25: PE | BK25: BA | BL25: SP | BM25: SC | BN25: Total Origem
B26: AM | D26: 6066 | E26: 8232 | F26: 3166 | G26: 54983 | H26: 5501 | I26: =SUM(C26:H26) -> 77948 | K26: AM | L26: =INT(C26/52) -> 0 | M26: =INT(D26/52) -> 116 | N26: =INT(E26/52) -> 158 | O26: =INT(F26/52) -> 60 | P26: =INT(G26/52) -> 1057 | Q26: =INT(H26/52) -> 105 | R26: =SUM(L26:Q26) -> 1496 | T26: AM | U26: =L32-R26 -> -339 | W26: AM | AD26: =SUM(X26:AC26) -> 0 | AF26: AM | AG26: =L26*28 -> 0 | AH26: =M26*28 -> 3248 | AI26: =N26*28 -> 4424 | AJ26: =O26*28 -> 1680 | AK26: =P26*28 -> 29596 | AL26: =Q26*28 -> 2940 | AM26: =SUM(AG26:AL26) -> 41888 | AO26: AM | AP26: =X26*4 -> 0 | AQ26: =Y26*4 -> 0 | AR26: =Z26*4 -> 0 | AS26: =AA26*4 -> 0 | AT26: =AB26*4 -> 0 | AU26: =AC26*4 -> 0 | AV26: =SUM(AP26:AU26) -> 0 | AX26: AM | AY26: =SUM(L6,2*L26,2*L46) -> 0 | AZ26: =SUM(M6,2*M26,2*M46) -> 265 | BA26: =SUM(N6,2*N26,2*N46) -> 322 | BB26: =SUM(O6,2*O26,2*O46) -> 126 | BC26: =SUM(P6,2*P26,2*P46) -> 2164 | BD26: =SUM(Q6,2*Q26,2*Q46) -> 219 | BE26: =SUM(AY26:BD26) -> 3096 | BG26: AM | BH26: =SUM(X6,2*X26,2*X46) -> 0 | BI26: =SUM(Y6,2*Y26,2*Y46) -> 0 | BJ26: =SUM(Z6,2*Z26,2*Z46) -> 0 | BK26: =SUM(AA6,2*AA26,2*AA46) -> 0 | BL26: =SUM(AB6,2*AB26,2*AB46) -> 56 | BM26: =SUM(AC6,2*AC26,2*AC46) -> 443 | BN26: =SUM(BH26:BM26) -> 499
B27: CE | C27: 10303 | E27: 2481 | F27: 101 | G27: 7856 | H27: 3188 | I27: =SUM(C27:H27) -> 23929 | K27: CE | L27: =INT(C27/52) -> 198 | M27: =INT(D27/52) -> 0 | N27: =INT(E27/52) -> 47 | O27: =INT(F27/52) -> 1 | P27: =INT(G27/52) -> 151 | Q27: =INT(H27/52) -> 61 | R27: =SUM(L27:Q27) -> 458 | T27: CE | U27: =M32-R27 -> 486 | W27: CE | X27: 339 | AC27: =U27-X27 -> 147 | AD27: =SUM(X27:AC27) -> 486 | AF27: CE | AG27: =L27*28 -> 5544 | AH27: =M27*28 -> 0 | AI27: =N27*28 -> 1316 | AJ27: =O27*28 -> 28 | AK27: =P27*28 -> 4228 | AL27: =Q27*28 -> 1708 | AM27: =SUM(AG27:AL27) -> 12824 | AO27: CE | AP27: =X27*4 -> 1356 | AQ27: =Y27*2 -> 0 | AR27: =Z27*2 -> 0 | AS27: =AA27*2 -> 0 | AT27: =AB27*4 -> 0 | AU27: =AC27*4 -> 588 | AV27: =SUM(AP27:AU27) -> 1944 | AX27: CE | AY27: =SUM(L7,2*L27,2*L47) -> 456 | AZ27: =SUM(M7,2*M27,2*M47) -> 0 | BA27: =SUM(N7,2*N27,2*N47) -> 99 | BB27: =SUM(O7,2*O27,2*O47) -> 11 | BC27: =SUM(P7,2*P27,2*P47) -> 485 | BD27: =SUM(Q7,2*Q27,2*Q47) -> 201 | BE27: =SUM(AY27:BD27) -> 1252 | BG27: CE | BH27: =SUM(X7,2*X27,2*X47) -> 678 | BI27: =SUM(Y7,2*Y27,2*Y47) -> 0 | BJ27: =SUM(Z7,2*Z27,2*Z47) -> 0 | BK27: =SUM(AA7,2*AA27,2*AA47) -> 0 | BL27: =SUM(AB7,2*AB27,2*AB47) -> 22 | BM27: =SUM(AC7,2*AC27,2*AC47) -> 606 | BN27: =SUM(BH27:BM27) -> 1306
B28: PE | C28: 17515 | D28: 5046 | F28: 652 | G28: 9764 | H28: 4287 | I28: =SUM(C28:H28) -> 37264 | K28: PE | L28: =INT(C28/52) -> 336 | M28: =INT(D28/52) -> 97 | N28: =INT(E28/52) -> 0 | O28: =INT(F28/52) -> 12 | P28: =INT(G28/52) -> 187 | Q28: =INT(H28/52) -> 82 | R28: =SUM(L28:Q28) -> 714 | T28: PE | U28: =N32-R28 -> 464 | W28: PE | AB28: =U28-AC28 -> 176 | AC28: =U29+U28 -> 288 | AD28: =SUM(X28:AC28) -> 464 | AF28: PE | AG28: =L28*28 -> 9408 | AH28: =M28*28 -> 2716 | AI28: =N28*28 -> 0 | AJ28: =O28*28 -> 336 | AK28: =P28*28 -> 5236 | AL28: =Q28*28 -> 2296 | AM28: =SUM(AG28:AL28) -> 19992 | AO28: PE | AP28: =X28*4 -> 0 | AQ28: =Y28*2 -> 0 | AR28: =Z28*2 -> 0 | AS28: =AA28*2 -> 0 | AT28: =AB28*4 -> 704 | AU28: =AC28*4 -> 1152 | AV28: =SUM(AP28:AU28) -> 1856 | AX28: PE | AY28: =SUM(L8,2*L28,2*L48) -> 771 | AZ28: =SUM(M8,2*M28,2*M48) -> 236 | BA28: =SUM(N8,2*N28,2*N48) -> 0 | BB28: =SUM(O8,2*O28,2*O48) -> 81 | BC28: =SUM(P8,2*P28,2*P48) -> 537 | BD28: =SUM(Q8,2*Q28,2*Q48) -> 179 | BE28: =SUM(AY28:BD28) -> 1804 | BG28: PE | BH28: =SUM(X8,2*X28,2*X48) -> 0 | BI28: =SUM(Y8,2*Y28,2*Y48) -> 0 | BJ28: =SUM(Z8,2*Z28,2*Z48) -> 0 | BK28: =SUM(AA8,2*AA28,2*AA48) -> 2 | BL28: =SUM(AB8,2*AB28,2*AB48) -> 570 | BM28: =SUM(AC8,2*AC28,2*AC48) -> 684 | BN28: =SUM(BH28:BM28) -> 1256
B29: BA | C29: 3252 | D29: 2029 | E29: 1364 | G29: 10648 | H29: 2531 | I29: =SUM(C29:H29) -> 19824 | K29: BA | L29: =INT(C29/52) -> 62 | M29: =INT(D29/52) -> 39 | N29: =INT(E29/52) -> 26 | O29: =INT(F29/52) -> 0 | P29: =INT(G29/52) -> 204 | Q29: =INT(H29/52) -> 48 | R29: =SUM(L29:Q29) -> 379 | T29: BA | U29: =O32-R29 -> -176 | W29: BA | AD29: =SUM(X29:AC29) -> 0 | AF29: BA | AG29: =L29*28 -> 1736 | AH29: =M29*28 -> 1092 | AI29: =N29*28 -> 728 | AJ29: =O29*28 -> 0 | AK29: =P29*28 -> 5712 | AL29: =Q29*28 -> 1344 | AM29: =SUM(AG29:AL29) -> 10612 | AO29: BA | AP29: =X29*4 -> 0 | AQ29: =Y29*2 -> 0 | AR29: =Z29*2 -> 0 | AS29: =AA29*2 -> 0 | AT29: =AB29*4 -> 0 | AU29: =AC29*4 -> 0 | AV29: =SUM(AP29:AU29) -> 0 | AX29: BA | AY29: =SUM(L9,2*L29,2*L49) -> 139 | AZ29: =SUM(M9,2*M29,2*M49) -> 104 | BA29: =SUM(N9,2*N29,2*N49) -> 76 | BB29: =SUM(O9,2*O29,2*O49) -> 0 | BC29: =SUM(P9,2*P29,2*P49) -> 641 | BD29: =SUM(Q9,2*Q29,2*Q49) -> 101 | BE29: =SUM(AY29:BD29) -> 1061 | BG29: BA | BH29: =SUM(X9,2*X29,2*X49) -> 0 | BI29: =SUM(Y9,2*Y29,2*Y49) -> 0 | BJ29: =SUM(Z9,2*Z29,2*Z49) -> 0 | BK29: =SUM(AA9,2*AA29,2*AA49) -> 0 | BL29: =SUM(AB9,2*AB29,2*AB49) -> 0 | BM29: =SUM(AC9,2*AC29,2*AC49) -> 0 | BN29: =SUM(BH29:BM29) -> 0
B30: SP | C30: 18041 | D30: 22859 | E30: 29225 | F30: 4383 | I30: =SUM(C30:H30) -> 74508 | K30: SP | L30: =INT(C30/52) -> 346 | M30: =INT(D30/52) -> 439 | N30: =INT(E30/52) -> 562 | O30: =INT(F30/52) -> 84 | P30: =INT(G30/52) -> 0 | Q30: =INT(H30/52) -> 0 | R30: =SUM(L30:Q30) -> 1431 | T30: SP | U30: =P32-R30 -> 168 | W30: SP | AC30: =U30 -> 168 | AD30: =SUM(X30:AC30) -> 168 | AF30: SP | AG30: =L30*28 -> 9688 | AH30: =M30*28 -> 12292 | AI30: =N30*28 -> 15736 | AJ30: =O30*28 -> 2352 | AK30: =P30*28 -> 0 | AL30: =Q30*28 -> 0 | AM30: =SUM(AG30:AL30) -> 40068 | AO30: SP | AP30: =X30*4 -> 0 | AQ30: =Y30*2 -> 0 | AR30: =Z30*2 -> 0 | AS30: =AA30*2 -> 0 | AT30: =AB30*4 -> 0 | AU30: =AC30*4 -> 672 | AV30: =SUM(AP30:AU30) -> 672 | AX30: SP | AY30: =SUM(L10,2*L30,2*L50) -> 858 | AZ30: =SUM(M10,2*M30,2*M50) -> 1088 | BA30: =SUM(N10,2*N30,2*N50) -> 1336 | BB30: =SUM(O10,2*O30,2*O50) -> 219 | BC30: =SUM(P10,2*P30,2*P50) -> 0 | BD30: =SUM(Q10,2*Q30,2*Q50) -> 0 | BE30: =SUM(AY30:BD30) -> 3501 | BG30: SP | BH30: =SUM(X10,2*X30,2*X50) -> 0 | BI30: =SUM(Y10,2*Y30,2*Y50) -> 0 | BJ30: =SUM(Z10,2*Z30,2*Z50) -> 0 | BK30: =SUM(AA10,2*AA30,2*AA50) -> 0 | BL30: =SUM(AB10,2*AB30,2*AB50) -> 0 | BM30: =SUM(AC10,2*AC30,2*AC50) -> 566 | BN30: =SUM(BH30:BM30) -> 566
B31: SC | C31: 11210 | D31: 13198 | E31: 20046 | F31: 2406 | I31: =SUM(C31:H31) -> 46860 | K31: SC | L31: =INT(C31/52) -> 215 | M31: =INT(D31/52) -> 253 | N31: =INT(E31/52) -> 385 | O31: =INT(F31/52) -> 46 | P31: =INT(G31/52) -> 0 | Q31: =INT(H31/52) -> 0 | R31: =SUM(L31:Q31) -> 899 | T31: SC | U31: =Q32-R31 -> -603 | W31: SC | AD31: =SUM(X31:AC31) -> 0 | AF31: SC | AG31: =L31*28 -> 6020 | AH31: =M31*28 -> 7084 | AI31: =N31*28 -> 10780 | AJ31: =O31*28 -> 1288 | AK31: =P31*28 -> 0 | AL31: =Q31*28 -> 0 | AM31: =SUM(AG31:AL31) -> 25172 | AO31: SC | AP31: =X31*4 -> 0 | AQ31: =Y31*2 -> 0 | AR31: =Z31*2 -> 0 | AS31: =AA31*2 -> 0 | AT31: =AB31*4 -> 0 | AU31: =AC31*4 -> 0 | AV31: =SUM(AP31:AU31) -> 0 | AX31: SC | AY31: =SUM(L11,2*L31,2*L51) -> 695 | AZ31: =SUM(M11,2*M31,2*M51) -> 865 | BA31: =SUM(N11,2*N31,2*N51) -> 1225 | BB31: =SUM(O11,2*O31,2*O51) -> 214 | BC31: =SUM(P11,2*P31,2*P51) -> 0 | BD31: =SUM(Q11,2*Q31,2*Q51) -> 0 | BE31: =SUM(AY31:BD31) -> 2999 | BG31: SC | BH31: =SUM(X11,2*X31,2*X51) -> 0 | BI31: =SUM(Y11,2*Y31,2*Y51) -> 0 | BJ31: =SUM(Z11,2*Z31,2*Z51) -> 0 | BK31: =SUM(AA11,2*AA31,2*AA51) -> 0 | BL31: =SUM(AB11,2*AB31,2*AB51) -> 0 | BM31: =SUM(AC11,2*AC31,2*AC51) -> 0 | BN31: =SUM(BH31:BM31) -> 0
