Workbook

Sheet Leia-me
A1: PNV-3421 · Aula 06 · Suavizamento Exponencial — planilha de apoio
A2: Suavizamento Exponencial Simples (SES), Método de Holt (tendência) e Holt-Winters (tendência + sazonalidade)
A4: Como usar
A5: Células AMARELAS com texto AZUL são parâmetros: altere-as e toda a planilha (tabelas, medidas de erro e gráficos) é recalculada.
A6: Linhas azul-claras = período de TREINO; linhas cinza = período de TESTE; linhas laranja-claras = inicialização do modelo.
A7: Convenção de erro: e = Y − Ŷ (real − previsto). MPE > 0 ⇒ o modelo subestima; MPE < 0 ⇒ superestima.
A9: Abas
A10: Dados | B10: As duas séries da aula: demanda trimestral por reparo naval (28 trimestres, 1990–1996) e consumo mensal de aço (15 meses).
A11: SES | B11: Suavizamento exponencial simples na série de reparo naval. Treino t=1–24, teste t=25–28.
A12: SES_varredura | B12: Calcula o MSE de treino do SES para α = 0,05; 0,10; …; 0,95 e mostra a curva MSE × α (sem precisar do Solver).
A13: SES_alfa | B13: Experimento α = 0,1 × α = 0,9: série sintética estável com ruído, um outlier (t=25) e uma mudança de patamar (t=41).
A14: Holt_Aco | B14: Método de Holt na série de aço (tendência pura). Treino t=1–11, teste t=12–15.
A15: Holt_Reparo | B15: Método de Holt na série de reparo naval: capta a tendência, mas não a sazonalidade.
A16: HoltWinters | B16: Holt-Winters multiplicativo (L=4) na série de reparo naval, com previsão operacional para 1997.
A17: Comparacao | B17: SES × Holt × Holt-Winters no mesmo período de teste (t=25–28), com gráfico.
A19: Dois protocolos de previsão no teste
A20: A · Origem fixa | B20: O modelo é ajustado até o fim do treino e prevê, de uma só vez, h = 1, 2, 3, 4 períodos à frente. Nenhum dado do teste é usado.
A21: B · Um passo à frente (rolling) | B21: Os parâmetros ficam fixos (escolhidos no treino), mas o modelo incorpora cada observação do teste assim que ela ocorre e prevê só o período seguinte.
A23: Escolhendo os parâmetros com o Solver (Dados → Solver)
A24: Objetivo | B24: Célula 'SSE' da coluna TREINO no quadro de medidas de erro de cada aba → Minimizar.
A25: Células variáveis | B25: As células amarelas de parâmetro (α; α e β; α, β e γ).
A26: Restrições | B26: 0 ≤ parâmetro ≤ 1. Método: GRG Não Linear (use 'Multistart' no Holt-Winters, que tem vários mínimos locais).
A27: Regra de ouro | B27: NUNCA inclua o período de teste no objetivo do Solver. O teste serve só para medir o erro de previsão.
A29: Valores iniciais dos parâmetros | B29: SES α=0,34, Holt_Aco (α=0,28; β=0,26) e Holt_Reparo (α=0,24; β=0,25) são os ótimos do treino encontrados no notebook. HoltWinters usa os parâmetros dos slides (α=0,8; β=0,1; γ=0,3); o ótimo do treino no notebook é (0,85; 0,10; 0,95).
A30: Fonte dos dados | B30: Séries da aula (slides 5 e 17), adaptadas de Hanke & Reitsch (1998), Business Forecasting, 6ª ed. A série da aba SES_alfa é sintética (nível 100 → 140 + ruído normal σ=10, semente 3421, outlier +45 em t=25).

Sheet Dados
A1: Dados da aula
A2: Série principal (treino t=1–24, teste t=25–28) e série de aço (treino t=1–11, teste t=12–15)
A4: t | B4: Ano | C4: Trimestre | D4: Demanda Y (unid. de serviço) | E4: Conjunto | G4: t (mês) | H4: Consumo de aço (t) | I4: Conjunto
A5: 1 | B5: 1990 | C5: 1 | D5: 500 | E5: Treino | G5: 1 | H5: 654 | I5: Treino
A6: 2 | B6: 1990 | C6: 2 | D6: 350 | E6: Treino | G6: 2 | H6: 658 | I6: Treino
A7: 3 | B7: 1990 | C7: 3 | D7: 250 | E7: Treino | G7: 3 | H7: 665 | I7: Treino
A8: 4 | B8: 1990 | C8: 4 | D8: 400 | E8: Treino | G8: 4 | H8: 672 | I8: Treino
A9: 5 | B9: 1991 | C9: 1 | D9: 450 | E9: Treino | G9: 5 | H9: 673 | I9: Treino
A10: 6 | B10: 1991 | C10: 2 | D10: 350 | E10: Treino | G10: 6 | H10: 671 | I10: Treino
A11: 7 | B11: 1991 | C11: 3 | D11: 200 | E11: Treino | G11: 7 | H11: 693 | I11: Treino
A12: 8 | B12: 1991 | C12: 4 | D12: 300 | E12: Treino | G12: 8 | H12: 694 | I12: Treino
A13: 9 | B13: 1992 | C13: 1 | D13: 350 | E13: Treino | G13: 9 | H13: 701 | I13: Treino
A14: 10 | B14: 1992 | C14: 2 | D14: 200 | E14: Treino | G14: 10 | H14: 703 | I14: Treino
A15: 11 | B15: 1992 | C15: 3 | D15: 150 | E15: Treino | G15: 11 | H15: 702 | I15: Treino
A16: 12 | B16: 1992 | C16: 4 | D16: 400 | E16: Treino | G16: 12 | H16: 710 | I16: Teste
... A19: 15 | B19: 1993 | C19: 3 | D19: 250 | E19: Treino | G19: 15 | H19: 728 | I19: Teste
A20: 16 | B20: 1993 | C20: 4 | D20: 550 | E20: Treino
A21: 17 | B21: 1994 | C21: 1 | D21: 550 | E21: Treino
A22: 18 | B22: 1994 | C22: 2 | D22: 400 | E22: Treino
A23: 19 | B23: 1994 | C23: 3 | D23: 350 | E23: Treino
A24: 20 | B24: 1994 | C24: 4 | D24: 600 | E24: Treino
A25: 21 | B25: 1995 | C25: 1 | D25: 750 | E25: Treino
A26: 22 | B26: 1995 | C26: 2 | D26: 500 | E26: Treino
A27: 23 | B27: 1995 | C27: 3 | D27: 400 | E27: Treino
A28: 24 | B28: 1995 | C28: 4 | D28: 650 | E28: Treino
A29: 25 | B29: 1996 | C29: 1 | D29: 850 | E29: Teste
A30: 26 | B30: 1996 | C30: 2 | D30: 600 | E30: Teste
A31: 27 | B31: 1996 | C31: 3 | D31: 450 | E31: Teste
A32: 28 | B32: 1996 | C32: 4 | D32: 700 | E32: Teste

Sheet SES
A1: Suavizamento Exponencial Simples (SES) — demanda de reparo naval
A2: S(t) = α·Y(t) + (1−α)·S(t−1) | Previsão: Ŷ(t+1) = S(t) (reta horizontal para qualquer horizonte) | Inicialização: S(1) = Y(1)
A4: α (nível) | B4: 0.33540571 | C4: ← altere aqui (0 < α < 1). Ótimo no treino ≈ 0,34
A6: Forma de correção de erro: S(t) = S(t−1) + α·[Y(t) − S(t−1)]
A7: Idade média dos dados = (1−α)/α = | D7: =(1-B4)/B4 -> 1.9814638 | E7: períodos
A8: MM equivalente n = (2−α)/α = | D8: =(2-B4)/B4 -> 4.9629276 | E8: períodos
A10: Medida | B10: TREINO (ajuste, t=2–24) | C10: TESTE A (origem fixa) | D10: TESTE B (rolling)
A11: MAD | B11: =AVERAGE(I21:I43) -> 126.27389 | C11: =AVERAGE(O44:O47) -> 151.47464 | D11: =AVERAGE(I44:I47) -> 165.69222 | F11: ← Solver: minimizar B16 (SSE do treino) alterando B4
A12: MSE | B12: =AVERAGE(J21:J43) -> 21420.14 | C12: =AVERAGE(P44:P47) -> 31848.554 | D12: =AVERAGE(J44:J47) -> 35997.047 | F12: Erro de previsão / erro de ajuste (MSE, teste B): | J12: =D12/B12 -> 1.6805235
A13: RMSE | B13: =SQRT(AVERAGE(J21:J43)) -> 146.35621 | C13: =SQRT(AVERAGE(P44:P47)) -> 178.46163 | D13: =SQRT(AVERAGE(J44:J47)) -> 189.72888
A14: MAPE | B14: =AVERAGE(K21:K43) -> 0.35372479 | C14: =AVERAGE(Q44:Q47) -> 0.21970674 | D14: =AVERAGE(K44:K47) -> 0.25668488
A15: MPE | B15: =AVERAGE(L21:L43) -> -0.11546239 | C15: =AVERAGE(R44:R47) -> 0.1118726 | D15: =AVERAGE(L44:L47) -> 0.013533233
A16: SSE | B16: =SUM(J21:J43) -> 492663.21 | C16: =SUM(P44:P47) -> 127394.22 | D16: =SUM(J44:J47) -> 143988.19
A17: n | B17: =COUNT(J21:J43) -> 23 | C17: =COUNT(P44:P47) -> 4 | D17: =COUNT(J44:J47) -> 4
A19: t | B19: Ano | C19: Trim. | D19: Conjunto | E19: Y | F19: S(t) nível | G19: Ŷ(t) = S(t−1) (1 passo, rolling) | H19: Erro e = Y − Ŷ | I19: |e| | J19: e² | K19: |e|/Y | L19: e/Y | M19: Ŷ origem fixa (= S(24)) | N19: Erro e = Y − Ŷ | O19: |e| | P19: e² | Q19: |e|/Y | R19: e/Y
A20: 1 | B20: 1990 | C20: 1 | D20: Treino | E20: =Dados!D5 -> 500 | F20: =E20 -> 500
A21: 2 | B21: 1990 | C21: 2 | D21: Treino | E21: =Dados!D6 -> 350 | F21: =$B$4*E21+(1-$B$4)*F20 -> 449.68914 | G21: =F20 -> 500 | H21: =E21-G21 -> -150 | I21: =ABS(H21) -> 150 | J21: =H21^2 -> 22500 | K21: =I21/E21 -> 0.42857143 | L21: =H21/E21 -> -0.42857143
A22: 3 | B22: 1990 | C22: 3 | D22: Treino | E22: =Dados!D7 -> 250 | F22: =$B$4*E22+(1-$B$4)*F21 -> 382.71226 | G22: =F21 -> 449.68914 | H22: =E22-G22 -> -199.68914 | I22: =ABS(H22) -> 199.68914 | J22: =H22^2 -> 39875.754 | K22: =I22/E22 -> 0.79875657 | L22: =H22/E22 -> -0.79875657
A23: 4 | B23: 1990 | C23: 4 | D23: Treino | E23: =Dados!D8 -> 400 | F23: =$B$4*E23+(1-$B$4)*F22 -> 388.51067 | G23: =F22 -> 382.71226 | H23: =E23-G23 -> 17.287736 | I23: =ABS(H23) -> 17.287736 | J23: =H23^2 -> 298.86583 | K23: =I23/E23 -> 0.043219341 | L23: =H23/E23 -> 0.043219341
A24: 5 | B24: 1991 | C24: 1 | D24: Treino | E24: =Dados!D9 -> 450 | F24: =$B$4*E24+(1-$B$4)*F23 -> 409.13454 | G24: =F23 -> 388.51067 | H24: =E24-G24 -> 61.489331 | I24: =ABS(H24) -> 61.489331 | J24: =H24^2 -> 3780.9378 | K24: =I24/E24 -> 0.13664296 | L24: =H24/E24 -> 0.13664296
A25: 6 | B25: 1991 | C25: 2 | D25: Treino | E25: =Dados!D10 -> 350 | F25: =$B$4*E25+(1-$B$4)*F24 -> 389.30048 | G25: =F24 -> 409.13454 | H25: =E25-G25 -> -59.134542 | I25: =ABS(H25) -> 59.134542 | J25: =H25^2 -> 3496.8941 | K25: =I25/E25 -> 0.16895583 | L25: =H25/E25 -> -0.16895583
A26: 7 | B26: 1991 | C26: 3 | D26: Treino | E26: =Dados!D11 -> 200 | F26: =$B$4*E26+(1-$B$4)*F25 -> 325.80802 | G26: =F25 -> 389.30048 | H26: =E26-G26 -> -189.30048 | I26: =ABS(H26) -> 189.30048 | J26: =H26^2 -> 35834.671 | K26: =I26/E26 -> 0.94650239 | L26: =H26/E26 -> -0.94650239
A27: 8 | B27: 1991 | C27: 4 | D27: Treino | E27: =Dados!D12 -> 300 | F27: =$B$4*E27+(1-$B$4)*F26 -> 317.15186 | G27: =F26 -> 325.80802 | H27: =E27-G27 -> -25.808017 | I27: =ABS(H27) -> 25.808017 | J27: =H27^2 -> 666.05372 | K27: =I27/E27 -> 0.086026722 | L27: =H27/E27 -> -0.086026722
A28: 9 | B28: 1992 | C28: 1 | D28: Treino | E28: =Dados!D13 -> 350 | F28: =$B$4*E28+(1-$B$4)*F27 -> 328.16931 | G28: =F27 -> 317.15186 | H28: =E28-G28 -> 32.84814 | I28: =ABS(H28) -> 32.84814 | J28: =H28^2 -> 1079.0003 | K28: =I28/E28 -> 0.093851827 | L28: =H28/E28 -> 0.093851827
A29: 10 | B29: 1992 | C29: 2 | D29: Treino | E29: =Dados!D14 -> 200 | F29: =$B$4*E29+(1-$B$4)*F28 -> 285.18059 | G29: =F28 -> 328.16931 | H29: =E29-G29 -> -128.16931 | I29: =ABS(H29) -> 128.16931 | J29: =H29^2 -> 16427.373 | K29: =I29/E29 -> 0.64084657 | L29: =H29/E29 -> -0.64084657
A30: 11 | B30: 1992 | C30: 3 | D30: Treino | E30: =Dados!D15 -> 150 | F30: =$B$4*E30+(1-$B$4)*F29 -> 239.84025 | G30: =F29 -> 285.18059 | H30: =E30-G30 -> -135.18059 | I30: =ABS(H30) -> 135.18059 | J30: =H30^2 -> 18273.793 | K30: =I30/E30 -> 0.90120396 | L30: =H30/E30 -> -0.90120396
A31: 12 | B31: 1992 | C31: 4 | D31: Treino | E31: =Dados!D16 -> 400 | F31: =$B$4*E31+(1-$B$4)*F30 -> 293.55875 | G31: =F30 -> 239.84025 | H31: =E31-G31 -> 160.15975 | I31: =ABS(H31) -> 160.15975 | J31: =H31^2 -> 25651.145 | K31: =I31/E31 -> 0.40039937 | L31: =H31/E31 -> 0.40039937
A32: 13 | B32: 1993 | C32: 1 | D32: Treino | E32: =Dados!D17 -> 550 | F32: =$B$4*E32+(1-$B$4)*F31 -> 379.57061 | G32: =F31 -> 293.55875 | H32: =E32-G32 -> 256.44125 | I32: =ABS(H32) -> 256.44125 | J32: =H32^2 -> 65762.117 | K32: =I32/E32 -> 0.46625683 | L32: =H32/E32 -> 0.46625683
... A43: 24 | B43: 1995 | C43: 4 | D43: Treino | E43: =Dados!D28 -> 650 | F43: =$B$4*E43+(1-$B$4)*F42 -> 547.05072 | G43: =F42 -> 495.09455 | H43: =E43-G43 -> 154.90545 | I43: =ABS(H43) -> 154.90545 | J43: =H43^2 -> 23995.699 | K43: =I43/E43 -> 0.23831608 | L43: =H43/E43 -> 0.23831608
A44: 25 | B44: 1996 | C44: 1 | D44: Teste | E44: =Dados!D29 -> 850 | F44: =$B$4*E44+(1-$B$4)*F43 -> 648.66164 | G44: =F43 -> 547.05072 | H44: =E44-G44 -> 302.94928 | I44: =ABS(H44) -> 302.94928 | J44: =H44^2 -> 91778.265 | K44: =I44/E44 -> 0.35641092 | L44: =H44/E44 -> 0.35641092 | M44: =$F$43 -> 547.05072 | N44: =E44-M44 -> 302.94928 | O44: =ABS(N44) -> 302.94928 | P44: =N44^2 -> 91778.265 | Q44: =O44/E44 -> 0.35641092 | R44: =N44/E44 -> 0.35641092
A45: 26 | B45: 1996 | C45: 2 | D45: Teste | E45: =Dados!D30 -> 600 | F45: =$B$4*E45+(1-$B$4)*F44 -> 632.34025 | G45: =F44 -> 648.66164 | H45: =E45-G45 -> -48.661641 | I45: =ABS(H45) -> 48.661641 | J45: =H45^2 -> 2367.9553 | K45: =I45/E45 -> 0.081102735 | L45: =H45/E45 -> -0.081102735 | M45: =$F$43 -> 547.05072 | N45: =E45-M45 -> 52.949278 | O45: =ABS(N45) -> 52.949278 | P45: =N45^2 -> 2803.626 | Q45: =O45/E45 -> 0.088248797 | R45: =N45/E45 -> 0.088248797
A46: 27 | B46: 1996 | C46: 3 | D46: Teste | E46: =Dados!D31 -> 450 | F46: =$B$4*E46+(1-$B$4)*F45 -> 571.18229 | G46: =F45 -> 632.34025 | H46: =E46-G46 -> -182.34025 | I46: =ABS(H46) -> 182.34025 | J46: =H46^2 -> 33247.966 | K46: =I46/E46 -> 0.40520055 | L46: =H46/E46 -> -0.40520055 | M46: =$F$43 -> 547.05072 | N46: =E46-M46 -> -97.050722 | O46: =ABS(N46) -> 97.050722 | P46: =N46^2 -> 9418.8427 | Q46: =O46/E46 -> 0.21566827 | R46: =N46/E46 -> -0.21566827
A47: 28 | B47: 1996 | C47: 4 | D47: Teste | E47: =Dados!D32 -> 700 | F47: =$B$4*E47+(1-$B$4)*F46 -> 614.38848 | G47: =F46 -> 571.18229 | H47: =E47-G47 -> 128.81771 | I47: =ABS(H47) -> 128.81771 | J47: =H47^2 -> 16594.003 | K47: =I47/E47 -> 0.1840253 | L47: =H47/E47 -> 0.1840253 | M47: =$F$43 -> 547.05072 | N47: =E47-M47 -> 152.94928 | O47: =ABS(N47) -> 152.94928 | P47: =N47^2 -> 23393.482 | Q47: =O47/E47 -> 0.21849897 | R47: =N47/E47 -> 0.21849897
G49: =F47 -> 614.38848 | I49: =AVERAGE(I44:I47) -> 165.69222 | J49: =AVERAGE(J44:J47) -> 35997.047 | K49: =AVERAGE(K44:K47) -> 0.25668488 | M49: =M47 -> 547.05072 | O49: =AVERAGE(O44:O47) -> 151.47464 | P49: =AVERAGE(P44:P47) -> 31848.554 | Q49: =AVERAGE(Q44:Q47) -> 0.21970674

Sheet SES_varredura
A1: SES — varredura de α no período de TREINO (t = 1–24)
A2: Cada coluna roda o SES com um α diferente; a linha MSE mostra o erro de ajuste. O teste (t=25–28) NÃO entra aqui.
A4: α | C4: 0.05 | D4: 0.1 | E4: 0.15 | F4: 0.2 | G4: 0.25 | H4: 0.3 | I4: 0.35 | J4: 0.4 | K4: 0.45 | L4: 0.5 | M4: 0.55 | N4: 0.6 | O4: 0.65 | P4: 0.7 | Q4: 0.75 | R4: 0.8 | S4: 0.85 | T4: 0.9 | U4: 0.95
A5: MSE treino | C5: =C6/23 -> 27233.616 | D5: =D6/23 -> 25316.573 | E5: =E6/23 -> 23715.501 | F5: =F6/23 -> 22539.243 | G5: =G6/23 -> 21819.72 | H5: =H6/23 -> 21481.406 | I5: =I6/23 -> 21429.427 | J5: =J6/23 -> 21582.88 | ... U5: =U6/23 -> 25877.128
A6: SSE treino | C6: =SUMPRODUCT(($B$10:$B$32-C9:C31)^2) -> 626373.16 | D6: =SUMPRODUCT(($B$10:$B$32-D9:D31)^2) -> 582281.18 | E6: =SUMPRODUCT(($B$10:$B$32-E9:E31)^2) -> 545456.53 | F6: =SUMPRODUCT(($B$10:$B$32-F9:F31)^2) -> 518402.59 | G6: =SUMPRODUCT(($B$10:$B$32-G9:G31)^2) -> 501853.57 | H6: =SUMPRODUCT(($B$10:$B$32-H9:H31)^2) -> 494072.34 | I6: =SUMPRODUCT(($B$10:$B$32-I9:I31)^2) -> 492876.83 | J6: =SUMPRODUCT(($B$10:$B$32-J9:J31)^2) -> 496406.25 | ... U6: =SUMPRODUCT(($B$10:$B$32-U9:U31)^2) -> 595173.94
A8: t | B8: Y | C8: S(t) α=0.05 | D8: S(t) α=0.10 | E8: S(t) α=0.15 | F8: S(t) α=0.20 | G8: S(t) α=0.25 | H8: S(t) α=0.30 | I8: S(t) α=0.35 | J8: S(t) α=0.40 | K8: S(t) α=0.45 | L8: S(t) α=0.50 | M8: S(t) α=0.55 | N8: S(t) α=0.60 | O8: S(t) α=0.65 | P8: S(t) α=0.70 | Q8: S(t) α=0.75 | R8: S(t) α=0.80 | S8: S(t) α=0.85 | T8: S(t) α=0.90 | U8: S(t) α=0.95
A9: 1 | B9: =Dados!D5 -> 500 | C9: =B9 -> 500 | D9: =B9 -> 500 | E9: =B9 -> 500 | F9: =B9 -> 500 | G9: =B9 -> 500 | H9: =B9 -> 500 | I9: =B9 -> 500 | J9: =B9 -> 500 | K9: =B9 -> 500 | L9: =B9 -> 500 | M9: =B9 -> 500 | N9: =B9 -> 500 | O9: =B9 -> 500 | P9: =B9 -> 500 | Q9: =B9 -> 500 | R9: =B9 -> 500 | S9: =B9 -> 500 | T9: =B9 -> 500 | U9: =B9 -> 500
A10: 2 | B10: =Dados!D6 -> 350 | C10: =C$4*B10+(1-C$4)*C9 -> 492.5 | D10: =D$4*B10+(1-D$4)*D9 -> 485 | E10: =E$4*B10+(1-E$4)*E9 -> 477.5 | F10: =F$4*B10+(1-F$4)*F9 -> 470 | G10: =G$4*B10+(1-G$4)*G9 -> 462.5 | H10: =H$4*B10+(1-H$4)*H9 -> 455 | I10: =I$4*B10+(1-I$4)*I9 -> 447.5 | J10: =J$4*B10+(1-J$4)*J9 -> 440 | K10: =K$4*B10+(1-K$4)*K9 -> 432.5 | L10: =L$4*B10+(1-L$4)*L9 -> 425 | M10: =M$4*B10+(1-M$4)*M9 -> 417.5 | N10: =N$4*B10+(1-N$4)*N9 -> 410 | O10: =O$4*B10+(1-O$4)*O9 -> 402.5 | P10: =P$4*B10+(1-P$4)*P9 -> 395 | Q10: =Q$4*B10+(1-Q$4)*Q9 -> 387.5 | R10: =R$4*B10+(1-R$4)*R9 -> 380 | S10: =S$4*B10+(1-S$4)*S9 -> 372.5 | T10: =T$4*B10+(1-T$4)*T9 -> 365 | U10: =U$4*B10+(1-U$4)*U9 -> 357.5
A11: 3 | B11: =Dados!D7 -> 250 | C11: =C$4*B11+(1-C$4)*C10 -> 480.375 | D11: =D$4*B11+(1-D$4)*D10 -> 461.5 | E11: =E$4*B11+(1-E$4)*E10 -> 443.375 | F11: =F$4*B11+(1-F$4)*F10 -> 426 | G11: =G$4*B11+(1-G$4)*G10 -> 409.375 | H11: =H$4*B11+(1-H$4)*H10 -> 393.5 | I11: =I$4*B11+(1-I$4)*I10 -> 378.375 | J11: =J$4*B11+(1-J$4)*J10 -> 364 | K11: =K$4*B11+(1-K$4)*K10 -> 350.375 | L11: =L$4*B11+(1-L$4)*L10 -> 337.5 | M11: =M$4*B11+(1-M$4)*M10 -> 325.375 | N11: =N$4*B11+(1-N$4)*N10 -> 314 | O11: =O$4*B11+(1-O$4)*O10 -> 303.375 | P11: =P$4*B11+(1-P$4)*P10 -> 293.5 | Q11: =Q$4*B11+(1-Q$4)*Q10 -> 284.375 | R11: =R$4*B11+(1-R$4)*R10 -> 276 | S11: =S$4*B11+(1-S$4)*S10 -> 268.375 | T11: =T$4*B11+(1-T$4)*T10 -> 261.5 | U11: =U$4*B11+(1-U$4)*U10 -> 255.375
A12: 4 | B12: =Dados!D8 -> 400 | C12: =C$4*B12+(1-C$4)*C11 -> 476.35625 | D12: =D$4*B12+(1-D$4)*D11 -> 455.35 | E12: =E$4*B12+(1-E$4)*E11 -> 436.86875 | F12: =F$4*B12+(1-F$4)*F11 -> 420.8 | G12: =G$4*B12+(1-G$4)*G11 -> 407.03125 | H12: =H$4*B12+(1-H$4)*H11 -> 395.45 | I12: =I$4*B12+(1-I$4)*I11 -> 385.94375 | J12: =J$4*B12+(1-J$4)*J11 -> 378.4 | K12: =K$4*B12+(1-K$4)*K11 -> 372.70625 | L12: =L$4*B12+(1-L$4)*L11 -> 368.75 | M12: =M$4*B12+(1-M$4)*M11 -> 366.41875 | N12: =N$4*B12+(1-N$4)*N11 -> 365.6 | O12: =O$4*B12+(1-O$4)*O11 -> 366.18125 | P12: =P$4*B12+(1-P$4)*P11 -> 368.05 | Q12: =Q$4*B12+(1-Q$4)*Q11 -> 371.09375 | R12: =R$4*B12+(1-R$4)*R11 -> 375.2 | S12: =S$4*B12+(1-S$4)*S11 -> 380.25625 | T12: =T$4*B12+(1-T$4)*T11 -> 386.15 | U12: =U$4*B12+(1-U$4)*U11 -> 392.76875
A13: 5 | B13: =Dados!D9 -> 450 | C13: =C$4*B13+(1-C$4)*C12 -> 475.03844 | D13: =D$4*B13+(1-D$4)*D12 -> 454.815 | E13: =E$4*B13+(1-E$4)*E12 -> 438.83844 | F13: =F$4*B13+(1-F$4)*F12 -> 426.64 | G13: =G$4*B13+(1-G$4)*G12 -> 417.77344 | H13: =H$4*B13+(1-H$4)*H12 -> 411.815 | I13: =I$4*B13+(1-I$4)*I12 -> 408.36344 | J13: =J$4*B13+(1-J$4)*J12 -> 407.04 | K13: =K$4*B13+(1-K$4)*K12 -> 407.48844 | L13: =L$4*B13+(1-L$4)*L12 -> 409.375 | M13: =M$4*B13+(1-M$4)*M12 -> 412.38844 | N13: =N$4*B13+(1-N$4)*N12 -> 416.24 | O13: =O$4*B13+(1-O$4)*O12 -> 420.66344 | P13: =P$4*B13+(1-P$4)*P12 -> 425.415 | Q13: =Q$4*B13+(1-Q$4)*Q12 -> 430.27344 | R13: =R$4*B13+(1-R$4)*R12 -> 435.04 | S13: =S$4*B13+(1-S$4)*S12 -> 439.53844 | T13: =T$4*B13+(1-T$4)*T12 -> 443.615 | U13: =U$4*B13+(1-U$4)*U12 -> 447.13844
A14: 6 | B14: =Dados!D10 -> 350 | C14: =C$4*B14+(1-C$4)*C13 -> 468.78652 | D14: =D$4*B14+(1-D$4)*D13 -> 444.3335 | E14: =E$4*B14+(1-E$4)*E13 -> 425.51267 | F14: =F$4*B14+(1-F$4)*F13 -> 411.312 | G14: =G$4*B14+(1-G$4)*G13 -> 400.83008 | H14: =H$4*B14+(1-H$4)*H13 -> 393.2705 | I14: =I$4*B14+(1-I$4)*I13 -> 387.93623 | J14: =J$4*B14+(1-J$4)*J13 -> 384.224 | K14: =K$4*B14+(1-K$4)*K13 -> 381.61864 | L14: =L$4*B14+(1-L$4)*L13 -> 379.6875 | M14: =M$4*B14+(1-M$4)*M13 -> 378.0748 | N14: =N$4*B14+(1-N$4)*N13 -> 376.496 | O14: =O$4*B14+(1-O$4)*O13 -> 374.7322 | P14: =P$4*B14+(1-P$4)*P13 -> 372.6245 | Q14: =Q$4*B14+(1-Q$4)*Q13 -> 370.06836 | R14: =R$4*B14+(1-R$4)*R13 -> 367.008 | S14: =S$4*B14+(1-S$4)*S13 -> 363.43077 | T14: =T$4*B14+(1-T$4)*T13 -> 359.3615 | U14: =U$4*B14+(1-U$4)*U13 -> 354.85692
A15: 7 | B15: =Dados!D11 -> 200 | C15: =C$4*B15+(1-C$4)*C14 -> 455.34719 | D15: =D$4*B15+(1-D$4)*D14 -> 419.90015 | E15: =E$4*B15+(1-E$4)*E14 -> 391.68577 | F15: =F$4*B15+(1-F$4)*F14 -> 369.0496 | G15: =G$4*B15+(1-G$4)*G14 -> 350.62256 | H15: =H$4*B15+(1-H$4)*H14 -> 335.28935 | I15: =I$4*B15+(1-I$4)*I14 -> 322.15855 | J15: =J$4*B15+(1-J$4)*J14 -> 310.5344 | K15: =K$4*B15+(1-K$4)*K14 -> 299.89025 | L15: =L$4*B15+(1-L$4)*L14 -> 289.84375 | M15: =M$4*B15+(1-M$4)*M14 -> 280.13366 | N15: =N$4*B15+(1-N$4)*N14 -> 270.5984 | O15: =O$4*B15+(1-O$4)*O14 -> 261.15627 | P15: =P$4*B15+(1-P$4)*P14 -> 251.78735 | Q15: =Q$4*B15+(1-Q$4)*Q14 -> 242.51709 | R15: =R$4*B15+(1-R$4)*R14 -> 233.4016 | S15: =S$4*B15+(1-S$4)*S14 -> 224.51461 | T15: =T$4*B15+(1-T$4)*T14 -> 215.93615 | U15: =U$4*B15+(1-U$4)*U14 -> 207.74285
A16: 8 | B16: =Dados!D12 -> 300 | C16: =C$4*B16+(1-C$4)*C15 -> 447.57983 | D16: =D$4*B16+(1-D$4)*D15 -> 407.91014 | E16: =E$4*B16+(1-E$4)*E15 -> 377.93291 | F16: =F$4*B16+(1-F$4)*F15 -> 355.23968 | G16: =G$4*B16+(1-G$4)*G15 -> 337.96692 | H16: =H$4*B16+(1-H$4)*H15 -> 324.70254 | I16: =I$4*B16+(1-I$4)*I15 -> 314.40306 | J16: =J$4*B16+(1-J$4)*J15 -> 306.32064 | K16: =K$4*B16+(1-K$4)*K15 -> 299.93964 | L16: =L$4*B16+(1-L$4)*L15 -> 294.92188 | M16: =M$4*B16+(1-M$4)*M15 -> 291.06015 | N16: =N$4*B16+(1-N$4)*N15 -> 288.23936 | O16: =O$4*B16+(1-O$4)*O15 -> 286.40469 | P16: =P$4*B16+(1-P$4)*P15 -> 285.5362 | Q16: =Q$4*B16+(1-Q$4)*Q15 -> 285.62927 | R16: =R$4*B16+(1-R$4)*R15 -> 286.68032 | S16: =S$4*B16+(1-S$4)*S15 -> 288.67719 | T16: =T$4*B16+(1-T$4)*T15 -> 291.59361 | U16: =U$4*B16+(1-U$4)*U15 -> 295.38714
A17: 9 | B17: =Dados!D13 -> 350 | C17: =C$4*B17+(1-C$4)*C16 -> 442.70084 | D17: =D$4*B17+(1-D$4)*D16 -> 402.11912 | E17: =E$4*B17+(1-E$4)*E16 -> 373.74297 | F17: =F$4*B17+(1-F$4)*F16 -> 354.19174 | G17: =G$4*B17+(1-G$4)*G16 -> 340.97519 | H17: =H$4*B17+(1-H$4)*H16 -> 332.29178 | I17: =I$4*B17+(1-I$4)*I16 -> 326.86199 | J17: =J$4*B17+(1-J$4)*J16 -> 323.79238 | K17: =K$4*B17+(1-K$4)*K16 -> 322.4668 | L17: =L$4*B17+(1-L$4)*L16 -> 322.46094 | M17: =M$4*B17+(1-M$4)*M16 -> 323.47707 | N17: =N$4*B17+(1-N$4)*N16 -> 325.29574 | O17: =O$4*B17+(1-O$4)*O16 -> 327.74164 | P17: =P$4*B17+(1-P$4)*P16 -> 330.66086 | Q17: =Q$4*B17+(1-Q$4)*Q16 -> 333.90732 | R17: =R$4*B17+(1-R$4)*R16 -> 337.33606 | S17: =S$4*B17+(1-S$4)*S16 -> 340.80158 | T17: =T$4*B17+(1-T$4)*T16 -> 344.15936 | U17: =U$4*B17+(1-U$4)*U16 -> 347.26936
A18: 10 | B18: =Dados!D14 -> 200 | C18: =C$4*B18+(1-C$4)*C17 -> 430.5658 | D18: =D$4*B18+(1-D$4)*D17 -> 381.90721 | E18: =E$4*B18+(1-E$4)*E17 -> 347.68152 | F18: =F$4*B18+(1-F$4)*F17 -> 323.3534 | G18: =G$4*B18+(1-G$4)*G17 -> 305.73139 | H18: =H$4*B18+(1-H$4)*H17 -> 292.60425 | I18: =I$4*B18+(1-I$4)*I17 -> 282.46029 | J18: =J$4*B18+(1-J$4)*J17 -> 274.27543 | K18: =K$4*B18+(1-K$4)*K17 -> 267.35674 | L18: =L$4*B18+(1-L$4)*L17 -> 261.23047 | M18: =M$4*B18+(1-M$4)*M17 -> 255.56468 | N18: =N$4*B18+(1-N$4)*N17 -> 250.1183 | O18: =O$4*B18+(1-O$4)*O17 -> 244.70958 | P18: =P$4*B18+(1-P$4)*P17 -> 239.19826 | Q18: =Q$4*B18+(1-Q$4)*Q17 -> 233.47683 | R18: =R$4*B18+(1-R$4)*R17 -> 227.46721 | S18: =S$4*B18+(1-S$4)*S17 -> 221.12024 | T18: =T$4*B18+(1-T$4)*T17 -> 214.41594 | U18: =U$4*B18+(1-U$4)*U17 -> 207.36347
A19: 11 | B19: =Dados!D15 -> 150 | C19: =C$4*B19+(1-C$4)*C18 -> 416.53751 | D19: =D$4*B19+(1-D$4)*D18 -> 358.71649 | E19: =E$4*B19+(1-E$4)*E18 -> 318.0293 | F19: =F$4*B19+(1-F$4)*F18 -> 288.68272 | G19: =G$4*B19+(1-G$4)*G18 -> 266.79854 | H19: =H$4*B19+(1-H$4)*H18 -> 249.82297 | I19: =I$4*B19+(1-I$4)*I18 -> 236.09919 | J19: =J$4*B19+(1-J$4)*J18 -> 224.56526 | K19: =K$4*B19+(1-K$4)*K18 -> 214.54621 | L19: =L$4*B19+(1-L$4)*L18 -> 205.61523 | M19: =M$4*B19+(1-M$4)*M18 -> 197.50411 | N19: =N$4*B19+(1-N$4)*N18 -> 190.04732 | O19: =O$4*B19+(1-O$4)*O18 -> 183.14835 | P19: =P$4*B19+(1-P$4)*P18 -> 176.75948 | Q19: =Q$4*B19+(1-Q$4)*Q18 -> 170.86921 | R19: =R$4*B19+(1-R$4)*R18 -> 165.49344 | S19: =S$4*B19+(1-S$4)*S18 -> 160.66804 | T19: =T$4*B19+(1-T$4)*T18 -> 156.44159 | U19: =U$4*B19+(1-U$4)*U18 -> 152.86817
A20: 12 | B20: =Dados!D16 -> 400 | C20: =C$4*B20+(1-C$4)*C19 -> 415.71063 | D20: =D$4*B20+(1-D$4)*D19 -> 362.84484 | E20: =E$4*B20+(1-E$4)*E19 -> 330.3249 | F20: =F$4*B20+(1-F$4)*F19 -> 310.94617 | G20: =G$4*B20+(1-G$4)*G19 -> 300.09891 | H20: =H$4*B20+(1-H$4)*H19 -> 294.87608 | I20: =I$4*B20+(1-I$4)*I19 -> 293.46447 | J20: =J$4*B20+(1-J$4)*J19 -> 294.73915 | K20: =K$4*B20+(1-K$4)*K19 -> 298.00041 | L20: =L$4*B20+(1-L$4)*L19 -> 302.80762 | M20: =M$4*B20+(1-M$4)*M19 -> 308.87685 | N20: =N$4*B20+(1-N$4)*N19 -> 316.01893 | O20: =O$4*B20+(1-O$4)*O19 -> 324.10192 | P20: =P$4*B20+(1-P$4)*P19 -> 333.02784 | Q20: =Q$4*B20+(1-Q$4)*Q19 -> 342.7173 | R20: =R$4*B20+(1-R$4)*R19 -> 353.09869 | S20: =S$4*B20+(1-S$4)*S19 -> 364.10021 | T20: =T$4*B20+(1-T$4)*T19 -> 375.64416 | U20: =U$4*B20+(1-U$4)*U19 -> 387.64341
A21: 13 | B21: =Dados!D17 -> 550 | C21: =C$4*B21+(1-C$4)*C20 -> 422.4251 | D21: =D$4*B21+(1-D$4)*D20 -> 381.56036 | E21: =E$4*B21+(1-E$4)*E20 -> 363.27617 | F21: =F$4*B21+(1-F$4)*F20 -> 358.75694 | G21: =G$4*B21+(1-G$4)*G20 -> 362.57418 | H21: =H$4*B21+(1-H$4)*H20 -> 371.41326 | I21: =I$4*B21+(1-I$4)*I20 -> 383.25191 | J21: =J$4*B21+(1-J$4)*J20 -> 396.84349 | K21: =K$4*B21+(1-K$4)*K20 -> 411.40023 | L21: =L$4*B21+(1-L$4)*L20 -> 426.40381 | M21: =M$4*B21+(1-M$4)*M20 -> 441.49458 | N21: =N$4*B21+(1-N$4)*N20 -> 456.40757 | O21: =O$4*B21+(1-O$4)*O20 -> 470.93567 | P21: =P$4*B21+(1-P$4)*P20 -> 484.90835 | Q21: =Q$4*B21+(1-Q$4)*Q20 -> 498.17933 | R21: =R$4*B21+(1-R$4)*R20 -> 510.61974 | S21: =S$4*B21+(1-S$4)*S20 -> 522.11503 | T21: =T$4*B21+(1-T$4)*T20 -> 532.56442 | U21: =U$4*B21+(1-U$4)*U20 -> 541.88217
... A32: 24 | B32: =Dados!D28 -> 650 | C32: =C$4*B32+(1-C$4)*C31 -> 454.97204 | D32: =D$4*B32+(1-D$4)*D31 -> 469.07476 | E32: =E$4*B32+(1-E$4)*E31 -> 493.42206 | F32: =F$4*B32+(1-F$4)*F31 -> 514.4288 | G32: =G$4*B32+(1-G$4)*G31 -> 529.99017 | H32: =H$4*B32+(1-H$4)*H31 -> 541.09518 | I32: =I$4*B32+(1-I$4)*I31 -> 549.17101 | J32: =J$4*B32+(1-J$4)*J31 -> 555.40314 | K32: =K$4*B32+(1-K$4)*K31 -> 560.66061 | L32: =L$4*B32+(1-L$4)*L31 -> 565.56465 | M32: =M$4*B32+(1-M$4)*M31 -> 570.56387 | N32: =N$4*B32+(1-N$4)*N31 -> 575.98687 | O32: =O$4*B32+(1-O$4)*O31 -> 582.07347 | P32: =P$4*B32+(1-P$4)*P31 -> 588.99168 | Q32: =Q$4*B32+(1-Q$4)*Q31 -> 596.84652 | R32: =R$4*B32+(1-R$4)*R31 -> 605.68498 | S32: =S$4*B32+(1-S$4)*S31 -> 615.49964 | T32: =T$4*B32+(1-T$4)*T31 -> 626.23256 | U32: =U$4*B32+(1-U$4)*U31 -> 637.78024
A34: Melhor α da grade: | C34: =INDEX(C4:U4,MATCH(MIN(C5:U5),C5:U5,0)) -> 0.35
A35: MSE mínimo: | C35: =MIN(C5:U5) -> 21429.427
A36: Refine com o Solver na aba SES (ótimo contínuo ≈ 0,335). Os valores de α desta linha 4 também podem ser editados.

Sheet SES_alfa
A1: Quando usar α = 0,1 e quando usar α = 0,9?
A2: Série SINTÉTICA: nível 100 (t=1–40) → 140 (t=41–60), ruído σ=10, outlier em t=25. α pequeno filtra ruído; α grande acompanha mudanças.
A4: α₁ (suave) | B4: 0.1 | AD4: k (defasagem) | AE4: peso α₁ | AF4: peso α₂
A5: α₂ (reativo) | B5: 0.9 | AD5: 0 | AE5: =$B$4*(1-$B$4)^AD5 -> 0.1 | AF5: =$B$5*(1-$B$5)^AD5 -> 0.9
AD6: 1 | AE6: =$B$4*(1-$B$4)^AD6 -> 0.09 | AF6: =$B$5*(1-$B$5)^AD6 -> 0.09
A7: Propriedade | B7: α₁ | C7: α₂ | D7: Interpretação | AD7: 2 | AE7: =$B$4*(1-$B$4)^AD7 -> 0.081 | AF7: =$B$5*(1-$B$5)^AD7 -> 0.009
A8: Peso do dado mais recente | B8: =$B$4 -> 0.1 | C8: =$B$5 -> 0.9 | D8: fração do erro que é corrigida a cada período | AD8: 3 | AE8: =$B$4*(1-$B$4)^AD8 -> 0.0729 | AF8: =$B$5*(1-$B$5)^AD8 -> 0.0009
A9: Idade média dos dados (períodos) | B9: =(1-$B$4)/$B$4 -> 9 | C9: =(1-$B$5)/$B$5 -> 0.11111111 | D9: quão 'antigas' são, em média, as observações usadas | AD9: 4 | AE9: =$B$4*(1-$B$4)^AD9 -> 0.06561 | AF9: =$B$5*(1-$B$5)^AD9 -> 9e-05
A10: Média móvel equivalente (n) | B10: =(2-$B$4)/$B$4 -> 19 | C10: =(2-$B$5)/$B$5 -> 1.2222222 | D10: MM com a mesma idade média | AD10: 5 | AE10: =$B$4*(1-$B$4)^AD10 -> 0.059049 | AF10: =$B$5*(1-$B$5)^AD10 -> 9e-06
A11: Meia-vida (períodos) | B11: =LN(0.5)/LN(1-$B$4) -> 6.5788135 | C11: =LN(0.5)/LN(1-$B$5) -> 0.30103 | D11: após quantos períodos um dado vale metade | AD11: 6 | AE11: =$B$4*(1-$B$4)^AD11 -> 0.0531441 | AF11: =$B$5*(1-$B$5)^AD11 -> 9e-07
A12: Variância da previsão (× σ² do ruído) | B12: =$B$4/(2-$B$4) -> 0.052631579 | C12: =$B$5/(2-$B$5) -> 0.81818182 | D12: quanto ruído passa para a previsão (série estável) | AD12: 7 | AE12: =$B$4*(1-$B$4)^AD12 -> 0.04782969 | AF12: =$B$5*(1-$B$5)^AD12 -> 9e-08
A13: Períodos p/ absorver 90% de um degrau | B13: =LN(0.1)/LN(1-$B$4) -> 21.854345 | C13: =LN(0.1)/LN(1-$B$5) -> 1 | D13: velocidade de reação a mudança de patamar | AD13: 8 | AE13: =$B$4*(1-$B$4)^AD13 -> 0.043046721 | AF13: =$B$5*(1-$B$5)^AD13 -> 9e-09
A14: Razão sinal-ruído q para a qual α é ótimo | B14: =$B$4^2/(1-$B$4) -> 0.011111111 | C14: =$B$5^2/(1-$B$5) -> 8.1 | D14: q = σ²(mudança de nível)/σ²(ruído) | AD14: 9 | AE14: =$B$4*(1-$B$4)^AD14 -> 0.038742049 | AF14: =$B$5*(1-$B$5)^AD14 -> 9e-10
AD15: 10 | AE15: =$B$4*(1-$B$4)^AD15 -> 0.034867844 | AF15: =$B$5*(1-$B$5)^AD15 -> 9e-11
A16: Trecho | B16: MSE α₁ | C16: MSE α₂ | D16: Vencedor | AD16: 11 | AE16: =$B$4*(1-$B$4)^AD16 -> 0.03138106 | AF16: =$B$5*(1-$B$5)^AD16 -> 9e-12
A17: Estável (t=2–40) | B17: =AVERAGE(G32:G70) -> 186.21079 | C17: =AVERAGE(J32:J70) -> 337.34476 | D17: =IF(B17<C17,"α₁ = "&FIXED($B$4,2),"α₂ = "&FIXED($B$5,2)) -> α₁ = 0,10 | AD17: 12 | AE17: =$B$4*(1-$B$4)^AD17 -> 0.028242954 | AF17: =$B$5*(1-$B$5)^AD17 -> 9e-13
A18: Logo após a mudança (t=41–50) | B18: =AVERAGE(G71:G80) -> 795.63468 | C18: =AVERAGE(J71:J80) -> 268.96477 | D18: =IF(B18<C18,"α₁ = "&FIXED($B$4,2),"α₂ = "&FIXED($B$5,2)) -> α₂ = 0,90 | AD18: 13 | AE18: =$B$4*(1-$B$4)^AD18 -> 0.025418658 | AF18: =$B$5*(1-$B$5)^AD18 -> 9e-14
A19: Novo patamar estabilizado (t=51–60) | B19: =AVERAGE(G81:G90) -> 191.89009 | C19: =AVERAGE(J81:J90) -> 174.68771 | D19: =IF(B19<C19,"α₁ = "&FIXED($B$4,2),"α₂ = "&FIXED($B$5,2)) -> α₂ = 0,90 | AD19: 14 | AE19: =$B$4*(1-$B$4)^AD19 -> 0.022876792 | AF19: =$B$5*(1-$B$5)^AD19 -> 9e-15
AD20: 15 | AE20: =$B$4*(1-$B$4)^AD20 -> 0.020589113 | AF20: =$B$5*(1-$B$5)^AD20 -> 9e-16
A21: Previsão para t=26 (logo após o outlier; real = 112): | B21: =F56 -> 107.43946 | C21: =I56 -> 135.5797
A23: Use α ≈ 0,1 quando… | B23: nível estável + ruído alto; outliers pontuais (greve, erro de registro); custo alto de reagir a alarmes falsos; horizonte de planejamento. Ex.: nível médio de maré, sobressalentes de rotina, demanda madura de docagem.
A24: Use α ≈ 0,9 quando… | B24: o nível muda com frequência e persiste (passeio aleatório); ruído baixo; mudança estrutural recente; custo alto de atraso. Ex.: preço do bunker, índices de frete, consumo logo após a entrada de novos navios.
A25: Alerta | B25: α ótimo próximo de 1 costuma denunciar tendência ou sazonalidade não modeladas → use Holt ou Holt-Winters, não um α maior.
A30: t | B30: Y | C30: Nível verdadeiro | D30: Trecho | E30: S(t) α₁ | F30: Ŷ(t) α₁ | G30: e² α₁ | H30: S(t) α₂ | I30: Ŷ(t) α₂ | J30: e² α₂
A31: 1 | B31: 113 | C31: 100 | D31: estável | E31: =B31 -> 113 | H31: =B31 -> 113
A32: 2 | B32: 96 | C32: 100 | D32: estável | E32: =$B$4*B32+(1-$B$4)*E31 -> 111.3 | F32: =E31 -> 113 | G32: =(B32-F32)^2 -> 289 | H32: =$B$5*B32+(1-$B$5)*H31 -> 97.7 | I32: =H31 -> 113 | J32: =(B32-I32)^2 -> 289
A33: 3 | B33: 105 | C33: 100 | D33: estável | E33: =$B$4*B33+(1-$B$4)*E32 -> 110.67 | F33: =E32 -> 111.3 | G33: =(B33-F33)^2 -> 39.69 | H33: =$B$5*B33+(1-$B$5)*H32 -> 104.27 | I33: =H32 -> 97.7 | J33: =(B33-I33)^2 -> 53.29
A34: 4 | B34: 105 | C34: 100 | D34: estável | E34: =$B$4*B34+(1-$B$4)*E33 -> 110.103 | F34: =E33 -> 110.67 | G34: =(B34-F34)^2 -> 32.1489 | H34: =$B$5*B34+(1-$B$5)*H33 -> 104.927 | I34: =H33 -> 104.27 | J34: =(B34-I34)^2 -> 0.5329
A35: 5 | B35: 84 | C35: 100 | D35: estável | E35: =$B$4*B35+(1-$B$4)*E34 -> 107.4927 | F35: =E34 -> 110.103 | G35: =(B35-F35)^2 -> 681.36661 | H35: =$B$5*B35+(1-$B$5)*H34 -> 86.0927 | I35: =H34 -> 104.927 | J35: =(B35-I35)^2 -> 437.93933
A36: 6 | B36: 110 | C36: 100 | D36: estável | E36: =$B$4*B36+(1-$B$4)*E35 -> 107.74343 | F36: =E35 -> 107.4927 | G36: =(B36-F36)^2 -> 6.2865533 | H36: =$B$5*B36+(1-$B$5)*H35 -> 107.60927 | I36: =H35 -> 86.0927 | J36: =(B36-I36)^2 -> 571.55899
A37: 7 | B37: 75 | C37: 100 | D37: estável | E37: =$B$4*B37+(1-$B$4)*E36 -> 104.46909 | F37: =E36 -> 107.74343 | G37: =(B37-F37)^2 -> 1072.1322 | H37: =$B$5*B37+(1-$B$5)*H36 -> 78.260927 | I37: =H36 -> 107.60927 | J37: =(B37-I37)^2 -> 1063.3645
A38: 8 | B38: 113 | C38: 100 | D38: estável | E38: =$B$4*B38+(1-$B$4)*E37 -> 105.32218 | F38: =E37 -> 104.46909 | G38: =(B38-F38)^2 -> 72.776477 | H38: =$B$5*B38+(1-$B$5)*H37 -> 109.52609 | I38: =H37 -> 78.260927 | J38: =(B38-I38)^2 -> 1206.8032
A39: 9 | B39: 100 | C39: 100 | D39: estável | E39: =$B$4*B39+(1-$B$4)*E38 -> 104.78996 | F39: =E38 -> 105.32218 | G39: =(B39-F39)^2 -> 28.325582 | H39: =$B$5*B39+(1-$B$5)*H38 -> 100.95261 | I39: =H38 -> 109.52609 | J39: =(B39-I39)^2 -> 90.746442
A40: 10 | B40: 108 | C40: 100 | D40: estável | E40: =$B$4*B40+(1-$B$4)*E39 -> 105.11096 | F40: =E39 -> 104.78996 | G40: =(B40-F40)^2 -> 10.304354 | H40: =$B$5*B40+(1-$B$5)*H39 -> 107.29526 | I40: =H39 -> 100.95261 | J40: =(B40-I40)^2 -> 49.665716
A41: 11 | B41: 89 | C41: 100 | D41: estável | E41: =$B$4*B41+(1-$B$4)*E40 -> 103.49987 | F41: =E40 -> 105.11096 | G41: =(B41-F41)^2 -> 259.56317 | H41: =$B$5*B41+(1-$B$5)*H40 -> 90.829526 | I41: =H40 -> 107.29526 | J41: =(B41-I41)^2 -> 334.71657
A42: 12 | B42: 117 | C42: 100 | D42: estável | E42: =$B$4*B42+(1-$B$4)*E41 -> 104.84988 | F42: =E41 -> 103.49987 | G42: =(B42-F42)^2 -> 182.25356 | H42: =$B$5*B42+(1-$B$5)*H41 -> 114.38295 | I42: =H41 -> 90.829526 | J42: =(B42-I42)^2 -> 684.8937
A43: 13 | B43: 93 | C43: 100 | D43: estável | E43: =$B$4*B43+(1-$B$4)*E42 -> 103.66489 | F43: =E42 -> 104.84988 | G43: =(B43-F43)^2 -> 140.41968 | H43: =$B$5*B43+(1-$B$5)*H42 -> 95.138295 | I43: =H42 -> 114.38295 | J43: =(B43-I43)^2 -> 457.23066
... A90: 60 | B90: 150 | C90: 140 | D90: novo patamar | E90: =$B$4*B90+(1-$B$4)*E89 -> 135.9839 | F90: =E89 -> 134.42656 | G90: =(B90-F90)^2 -> 242.53209 | H90: =$B$5*B90+(1-$B$5)*H89 -> 150.18626 | I90: =H89 -> 151.86258 | J90: =(B90-I90)^2 -> 3.469199

Sheet Holt_Aco
A1: Método de Holt — consumo mensal de aço naval
A2: A(t)=α·Y(t)+(1−α)[A(t−1)+T(t−1)] | T(t)=β[A(t)−A(t−1)]+(1−β)T(t−1) | Ŷ(t+p)=A(t)+p·T(t) | Início: A(2)=Y(2), T(2)=Y(2)−Y(1)
A4: α (nível) | B4: 0.28 | C4: ← 0 < α < 1
A5: β (tendência) | B5: 0.26 | C5: ← 0 < β < 1
A6: Referência dos slides (mesmo teste t=12–15): média móvel n=3 → MSE 102,8; média móvel dupla n=3 → MSE 34,1.
A10: Medida | B10: TREINO (ajuste, t=3–11) | C10: TESTE A (origem fixa) | D10: TESTE B (rolling)
A11: MAD | B11: =AVERAGE(I22:I30) -> 5.0506249 | C11: =AVERAGE(O31:O34) -> 5.0352592 | D11: =AVERAGE(I31:I34) -> 5.6258437 | F11: ← Solver: minimizar B16 (SSE do treino) alterando B4:B5
A12: MSE | B12: =AVERAGE(J22:J30) -> 39.471806 | C12: =AVERAGE(P31:P34) -> 44.932932 | D12: =AVERAGE(J31:J34) -> 38.120037
A13: RMSE | B13: =SQRT(AVERAGE(J22:J30)) -> 6.2826591 | C13: =SQRT(AVERAGE(P31:P34)) -> 6.7032031 | D13: =SQRT(AVERAGE(J31:J34)) -> 6.1741426
A14: MAPE | B14: =AVERAGE(K22:K30) -> 0.00734244 | C14: =AVERAGE(Q31:Q34) -> 0.0070776482 | D14: =AVERAGE(K31:K34) -> 0.0078609636
A15: MPE | B15: =AVERAGE(L22:L30) -> 0.0030020042 | C15: =AVERAGE(R31:R34) -> -0.0070776482 | D15: =AVERAGE(L31:L34) -> -0.0036491252
A16: SSE | B16: =SUM(J22:J30) -> 355.24625 | C16: =SUM(P31:P34) -> 179.73173 | D16: =SUM(J31:J34) -> 152.48015
A17: n | B17: =COUNT(J22:J30) -> 9 | C17: =COUNT(P31:P34) -> 4 | D17: =COUNT(J31:J34) -> 4
A19: t | B19: Rótulo | C19: Conjunto | D19: Y | E19: A(t) nível | F19: T(t) tendência | G19: Ŷ(t) = A(t−1)+T(t−1) (1 passo, rolling) | H19: Erro e = Y − Ŷ | I19: |e| | J19: e² | K19: |e|/Y | L19: e/Y | M19: Ŷ origem fixa = A(fim treino) + p·T(fim treino) | N19: Erro e = Y − Ŷ | O19: |e| | P19: e² | Q19: |e|/Y | R19: e/Y
A20: 1 | B20: mês 1 | C20: Treino | D20: =Dados!H5 -> 654
A21: 2 | B21: mês 2 | C21: Treino | D21: =Dados!H6 -> 658 | E21: =D21 -> 658 | F21: =D21-D20 -> 4
A22: 3 | B22: mês 3 | C22: Treino | D22: =Dados!H7 -> 665 | E22: =$B$4*D22+(1-$B$4)*(E21+F21) -> 662.84 | F22: =$B$5*(E22-E21)+(1-$B$5)*F21 -> 4.2184 | G22: =E21+F21 -> 662 | H22: =D22-G22 -> 3 | I22: =ABS(H22) -> 3 | J22: =H22^2 -> 9 | K22: =I22/D22 -> 0.0045112782 | L22: =H22/D22 -> 0.0045112782
A23: 4 | B23: mês 4 | C23: Treino | D23: =Dados!H8 -> 672 | E23: =$B$4*D23+(1-$B$4)*(E22+F22) -> 668.44205 | F23: =$B$5*(E23-E22)+(1-$B$5)*F22 -> 4.5781485 | G23: =E22+F22 -> 667.0584 | H23: =D23-G23 -> 4.9416 | I23: =ABS(H23) -> 4.9416 | J23: =H23^2 -> 24.419411 | K23: =I23/D23 -> 0.0073535714 | L23: =H23/D23 -> 0.0073535714
A24: 5 | B24: mês 5 | C24: Treino | D24: =Dados!H9 -> 673 | E24: =$B$4*D24+(1-$B$4)*(E23+F23) -> 673.01454 | F24: =$B$5*(E24-E23)+(1-$B$5)*F23 -> 4.5766782 | G24: =E23+F23 -> 673.0202 | H24: =D24-G24 -> -0.02019648 | I24: =ABS(H24) -> 0.02019648 | J24: =H24^2 -> 0.0004078978 | K24: =I24/D24 -> 3.0009629e-05 | L24: =H24/D24 -> -3.0009629e-05
A25: 6 | B25: mês 6 | C25: Treino | D25: =Dados!H10 -> 671 | E25: =$B$4*D25+(1-$B$4)*(E24+F24) -> 675.74568 | F25: =$B$5*(E25-E24)+(1-$B$5)*F24 -> 4.0968374 | G25: =E24+F24 -> 677.59122 | H25: =D25-G25 -> -6.5912196 | I25: =ABS(H25) -> 6.5912196 | J25: =H25^2 -> 43.444176 | K25: =I25/D25 -> 0.0098229801 | L25: =H25/D25 -> -0.0098229801
A26: 7 | B26: mês 7 | C26: Treino | D26: =Dados!H11 -> 693 | E26: =$B$4*D26+(1-$B$4)*(E25+F25) -> 683.52661 | F26: =$B$5*(E26-E25)+(1-$B$5)*F25 -> 5.0547023 | G26: =E25+F25 -> 679.84252 | H26: =D26-G26 -> 13.157484 | I26: =ABS(H26) -> 13.157484 | J26: =H26^2 -> 173.1194 | K26: =I26/D26 -> 0.018986269 | L26: =H26/D26 -> 0.018986269
A27: 8 | B27: mês 8 | C27: Treino | D27: =Dados!H12 -> 694 | E27: =$B$4*D27+(1-$B$4)*(E26+F26) -> 690.09855 | F27: =$B$5*(E27-E26)+(1-$B$5)*F26 -> 5.4491826 | G27: =E26+F26 -> 688.58131 | H27: =D27-G27 -> 5.4186866 | I27: =ABS(H27) -> 5.4186866 | J27: =H27^2 -> 29.362164 | K27: =I27/D27 -> 0.0078079057 | L27: =H27/D27 -> 0.0078079057
A28: 9 | B28: mês 9 | C28: Treino | D28: =Dados!H13 -> 701 | E28: =$B$4*D28+(1-$B$4)*(E27+F27) -> 697.07436 | F28: =$B$5*(E28-E27)+(1-$B$5)*F27 -> 5.846108 | G28: =E27+F27 -> 695.54773 | H28: =D28-G28 -> 5.4522717 | I28: =ABS(H28) -> 5.4522717 | J28: =H28^2 -> 29.727267 | K28: =I28/D28 -> 0.0077778483 | L28: =H28/D28 -> 0.0077778483
A29: 10 | B29: mês 10 | C29: Treino | D29: =Dados!H14 -> 703 | E29: =$B$4*D29+(1-$B$4)*(E28+F28) -> 702.94274 | F29: =$B$5*(E29-E28)+(1-$B$5)*F28 -> 5.8518976 | G29: =E28+F28 -> 702.92047 | H29: =D29-G29 -> 0.079527599 | I29: =ABS(H29) -> 0.079527599 | J29: =H29^2 -> 0.006324639 | K29: =I29/D29 -> 0.00011312603 | L29: =H29/D29 -> 0.00011312603
A30: 11 | B30: mês 11 | C30: Treino | D30: =Dados!H15 -> 702 | E30: =$B$4*D30+(1-$B$4)*(E29+F29) -> 706.89214 | F30: =$B$5*(E30-E29)+(1-$B$5)*F29 -> 5.357248 | G30: =E29+F29 -> 708.79464 | H30: =D30-G30 -> -6.7946378 | I30: =ABS(H30) -> 6.7946378 | J30: =H30^2 -> 46.167102 | K30: =I30/D30 -> 0.0096789712 | L30: =H30/D30 -> -0.0096789712
A31: 12 | B31: mês 12 | C31: Teste | D31: =Dados!H16 -> 710 | E31: =$B$4*D31+(1-$B$4)*(E30+F30) -> 711.61956 | F31: =$B$5*(E31-E30)+(1-$B$5)*F30 -> 5.1934926 | G31: =E30+F30 -> 712.24939 | H31: =D31-G31 -> -2.2493872 | I31: =ABS(H31) -> 2.2493872 | J31: =H31^2 -> 5.0597427 | K31: =I31/D31 -> 0.003168151 | L31: =H31/D31 -> -0.003168151 | M31: =$E$30+(A31-11)*$F$30 -> 712.24939 | N31: =D31-M31 -> -2.2493872 | O31: =ABS(N31) -> 2.2493872 | P31: =N31^2 -> 5.0597427 | Q31: =O31/D31 -> 0.003168151 | R31: =N31/D31 -> -0.003168151
A32: 13 | B32: mês 13 | C32: Teste | D32: =Dados!H17 -> 712 | E32: =$B$4*D32+(1-$B$4)*(E31+F31) -> 715.4654 | F32: =$B$5*(E32-E31)+(1-$B$5)*F31 -> 4.8431025 | G32: =E31+F31 -> 716.81305 | H32: =D32-G32 -> -4.8130514 | I32: =ABS(H32) -> 4.8130514 | J32: =H32^2 -> 23.165464 | K32: =I32/D32 -> 0.0067599036 | L32: =H32/D32 -> -0.0067599036 | M32: =$E$30+(A32-11)*$F$30 -> 717.60664 | N32: =D32-M32 -> -5.6066352 | O32: =ABS(N32) -> 5.6066352 | P32: =N32^2 -> 31.434358 | Q32: =O32/D32 -> 0.0078744876 | R32: =N32/D32 -> -0.0078744876
A33: 14 | B33: mês 14 | C33: Teste | D33: =Dados!H18 -> 711 | E33: =$B$4*D33+(1-$B$4)*(E32+F32) -> 717.70212 | F33: =$B$5*(E33-E32)+(1-$B$5)*F32 -> 4.1654437 | G33: =E32+F32 -> 720.3085 | H33: =D33-G33 -> -9.3084995 | I33: =ABS(H33) -> 9.3084995 | J33: =H33^2 -> 86.648162 | K33: =I33/D33 -> 0.013092123 | L33: =H33/D33 -> -0.013092123 | M33: =$E$30+(A33-11)*$F$30 -> 722.96388 | N33: =D33-M33 -> -11.963883 | O33: =ABS(N33) -> 11.963883 | P33: =N33^2 -> 143.1345 | Q33: =O33/D33 -> 0.01682684 | R33: =N33/D33 -> -0.01682684
A34: 15 | B34: mês 15 | C34: Teste | D34: =Dados!H19 -> 728 | E34: =$B$4*D34+(1-$B$4)*(E33+F33) -> 723.58465 | F34: =$B$5*(E34-E33)+(1-$B$5)*F33 -> 4.6118851 | G34: =E33+F33 -> 721.86756 | H34: =D34-G34 -> 6.1324367 | I34: =ABS(H34) -> 6.1324367 | J34: =H34^2 -> 37.60678 | K34: =I34/D34 -> 0.0084236768 | L34: =H34/D34 -> 0.0084236768 | M34: =$E$30+(A34-11)*$F$30 -> 728.32113 | N34: =D34-M34 -> -0.32113117 | O34: =ABS(N34) -> 0.32113117 | P34: =N34^2 -> 0.10312523 | Q34: =O34/D34 -> 0.00044111425 | R34: =N34/D34 -> -0.00044111425

Sheet Holt_Reparo
A1: Método de Holt — demanda de reparo naval
A2: Mesmas equações; início pelo 1º ano: A(4)=média(Y1..Y4), T(4)=[média(Y5..Y8) − média(Y1..Y4)]/4. Capta a tendência, não a sazonalidade.
A4: α (nível) | B4: 0.24 | C4: ← 0 < α < 1
A5: β (tendência) | B5: 0.25 | C5: ← 0 < β < 1
A6: Observe no gráfico: a previsão 'passa pelo meio' do ciclo sazonal — erra para baixo no T1 e para cima no T3.
A10: Medida | B10: TREINO (ajuste, t=5–24) | C10: TESTE A (origem fixa) | D10: TESTE B (rolling)
A11: MAD | B11: =AVERAGE(I24:I43) -> 125.166 | C11: =AVERAGE(O44:O47) -> 125 | D11: =AVERAGE(I44:I47) -> 160.42198 | F11: ← Solver: minimizar B16 (SSE do treino) alterando B4:B5
A12: MSE | B12: =AVERAGE(J24:J43) -> 22178.797 | C12: =AVERAGE(P44:P47) -> 25663.066 | D12: =AVERAGE(J44:J47) -> 34375.863
A13: RMSE | B13: =SQRT(AVERAGE(J24:J43)) -> 148.92547 | C13: =SQRT(AVERAGE(P44:P47)) -> 160.19696 | D13: =SQRT(AVERAGE(J44:J47)) -> 185.40729
A14: MAPE | B14: =AVERAGE(K24:K43) -> 0.32267949 | C14: =AVERAGE(Q44:Q47) -> 0.21138657 | D14: =AVERAGE(K44:K47) -> 0.27520221
A15: MPE | B15: =AVERAGE(L24:L43) -> -0.027393639 | C15: =AVERAGE(R44:R47) -> -0.07619049 | D15: =AVERAGE(L44:L47) -> -0.12017767
A16: SSE | B16: =SUM(J24:J43) -> 443575.94 | C16: =SUM(P44:P47) -> 102652.26 | D16: =SUM(J44:J47) -> 137503.45
A17: n | B17: =COUNT(J24:J43) -> 20 | C17: =COUNT(P44:P47) -> 4 | D17: =COUNT(J44:J47) -> 4
A19: t | B19: Rótulo | C19: Conjunto | D19: Y | E19: A(t) nível | F19: T(t) tendência | G19: Ŷ(t) = A(t−1)+T(t−1) (1 passo, rolling) | H19: Erro e = Y − Ŷ | I19: |e| | J19: e² | K19: |e|/Y | L19: e/Y | M19: Ŷ origem fixa = A(fim treino) + p·T(fim treino) | N19: Erro e = Y − Ŷ | O19: |e| | P19: e² | Q19: |e|/Y | R19: e/Y
A20: 1 | B20: 1990-T1 | C20: Treino | D20: =Dados!D5 -> 500
A21: 2 | B21: 1990-T2 | C21: Treino | D21: =Dados!D6 -> 350
A22: 3 | B22: 1990-T3 | C22: Treino | D22: =Dados!D7 -> 250
A23: 4 | B23: 1990-T4 | C23: Treino | D23: =Dados!D8 -> 400 | E23: =AVERAGE(D20:D23) -> 375 | F23: =(AVERAGE(D24:D27)-AVERAGE(D20:D23))/4 -> -12.5
A24: 5 | B24: 1991-T1 | C24: Treino | D24: =Dados!D9 -> 450 | E24: =$B$4*D24+(1-$B$4)*(E23+F23) -> 383.5 | F24: =$B$5*(E24-E23)+(1-$B$5)*F23 -> -7.25 | G24: =E23+F23 -> 362.5 | H24: =D24-G24 -> 87.5 | I24: =ABS(H24) -> 87.5 | J24: =H24^2 -> 7656.25 | K24: =I24/D24 -> 0.19444444 | L24: =H24/D24 -> 0.19444444
A25: 6 | B25: 1991-T2 | C25: Treino | D25: =Dados!D10 -> 350 | E25: =$B$4*D25+(1-$B$4)*(E24+F24) -> 369.95 | F25: =$B$5*(E25-E24)+(1-$B$5)*F24 -> -8.825 | G25: =E24+F24 -> 376.25 | H25: =D25-G25 -> -26.25 | I25: =ABS(H25) -> 26.25 | J25: =H25^2 -> 689.0625 | K25: =I25/D25 -> 0.075 | L25: =H25/D25 -> -0.075
A26: 7 | B26: 1991-T3 | C26: Treino | D26: =Dados!D11 -> 200 | E26: =$B$4*D26+(1-$B$4)*(E25+F25) -> 322.455 | F26: =$B$5*(E26-E25)+(1-$B$5)*F25 -> -18.4925 | G26: =E25+F25 -> 361.125 | H26: =D26-G26 -> -161.125 | I26: =ABS(H26) -> 161.125 | J26: =H26^2 -> 25961.266 | K26: =I26/D26 -> 0.805625 | L26: =H26/D26 -> -0.805625
A27: 8 | B27: 1991-T4 | C27: Treino | D27: =Dados!D12 -> 300 | E27: =$B$4*D27+(1-$B$4)*(E26+F26) -> 303.0115 | F27: =$B$5*(E27-E26)+(1-$B$5)*F26 -> -18.73025 | G27: =E26+F26 -> 303.9625 | H27: =D27-G27 -> -3.9625 | I27: =ABS(H27) -> 3.9625 | J27: =H27^2 -> 15.701406 | K27: =I27/D27 -> 0.013208333 | L27: =H27/D27 -> -0.013208333
A28: 9 | B28: 1992-T1 | C28: Treino | D28: =Dados!D13 -> 350 | E28: =$B$4*D28+(1-$B$4)*(E27+F27) -> 300.05375 | F28: =$B$5*(E28-E27)+(1-$B$5)*F27 -> -14.787125 | G28: =E27+F27 -> 284.28125 | H28: =D28-G28 -> 65.71875 | I28: =ABS(H28) -> 65.71875 | J28: =H28^2 -> 4318.9541 | K28: =I28/D28 -> 0.18776786 | L28: =H28/D28 -> 0.18776786
A29: 10 | B29: 1992-T2 | C29: Treino | D29: =Dados!D14 -> 200 | E29: =$B$4*D29+(1-$B$4)*(E28+F28) -> 264.80263 | F29: =$B$5*(E29-E28)+(1-$B$5)*F28 -> -19.903123 | G29: =E28+F28 -> 285.26662 | H29: =D29-G29 -> -85.266625 | I29: =ABS(H29) -> 85.266625 | J29: =H29^2 -> 7270.3973 | K29: =I29/D29 -> 0.42633312 | L29: =H29/D29 -> -0.42633312
A30: 11 | B30: 1992-T3 | C30: Treino | D30: =Dados!D15 -> 150 | E30: =$B$4*D30+(1-$B$4)*(E29+F29) -> 222.12363 | F30: =$B$5*(E30-E29)+(1-$B$5)*F29 -> -25.597093 | G30: =E29+F29 -> 244.89951 | H30: =D30-G30 -> -94.899512 | I30: =ABS(H30) -> 94.899512 | J30: =H30^2 -> 9005.9175 | K30: =I30/D30 -> 0.63266342 | L30: =H30/D30 -> -0.63266342
A31: 12 | B31: 1992-T4 | C31: Treino | D31: =Dados!D16 -> 400 | E31: =$B$4*D31+(1-$B$4)*(E30+F30) -> 245.36017 | F31: =$B$5*(E31-E30)+(1-$B$5)*F30 -> -13.388685 | G31: =E30+F30 -> 196.52654 | H31: =D31-G31 -> 203.47346 | I31: =ABS(H31) -> 203.47346 | J31: =H31^2 -> 41401.45 | K31: =I31/D31 -> 0.50868366 | L31: =H31/D31 -> 0.50868366
A32: 13 | B32: 1993-T1 | C32: Treino | D32: =Dados!D17 -> 550 | E32: =$B$4*D32+(1-$B$4)*(E31+F31) -> 308.29833 | F32: =$B$5*(E32-E31)+(1-$B$5)*F31 -> 5.6930256 | G32: =E31+F31 -> 231.97148 | H32: =D32-G32 -> 318.02852 | I32: =ABS(H32) -> 318.02852 | J32: =H32^2 -> 101142.14 | K32: =I32/D32 -> 0.57823367 | L32: =H32/D32 -> 0.57823367
A33: 14 | B33: 1993-T2 | C33: Treino | D33: =Dados!D18 -> 350 | E33: =$B$4*D33+(1-$B$4)*(E32+F32) -> 322.63343 | F33: =$B$5*(E33-E32)+(1-$B$5)*F32 -> 7.8535445 | G33: =E32+F32 -> 313.99135 | H33: =D33-G33 -> 36.008648 | I33: =ABS(H33) -> 36.008648 | J33: =H33^2 -> 1296.6227 | K33: =I33/D33 -> 0.10288185 | L33: =H33/D33 -> 0.10288185
A34: 15 | B34: 1993-T3 | C34: Treino | D34: =Dados!D19 -> 250 | E34: =$B$4*D34+(1-$B$4)*(E33+F33) -> 311.1701 | F34: =$B$5*(E34-E33)+(1-$B$5)*F33 -> 3.0243262 | G34: =E33+F33 -> 330.48697 | H34: =D34-G34 -> -80.486972 | I34: =ABS(H34) -> 80.486972 | J34: =H34^2 -> 6478.1527 | K34: =I34/D34 -> 0.32194789 | L34: =H34/D34 -> -0.32194789
A35: 16 | B35: 1993-T4 | C35: Treino | D35: =Dados!D20 -> 550 | E35: =$B$4*D35+(1-$B$4)*(E34+F34) -> 370.78776 | F35: =$B$5*(E35-E34)+(1-$B$5)*F34 -> 17.172661 | G35: =E34+F34 -> 314.19442 | H35: =D35-G35 -> 235.80558 | I35: =ABS(H35) -> 235.80558 | J35: =H35^2 -> 55604.269 | K35: =I35/D35 -> 0.42873741 | L35: =H35/D35 -> 0.42873741
... A43: 24 | B43: 1995-T4 | C43: Treino | D43: =Dados!D28 -> 650 | E43: =$B$4*D43+(1-$B$4)*(E42+F42) -> 600.67201 | F43: =$B$5*(E43-E42)+(1-$B$5)*F42 -> 23.920743 | G43: =E42+F42 -> 585.09475 | H43: =D43-G43 -> 64.905253 | I43: =ABS(H43) -> 64.905253 | J43: =H43^2 -> 4212.6919 | K43: =I43/D43 -> 0.099854235 | L43: =H43/D43 -> 0.099854235
A44: 25 | B44: 1996-T1 | C44: Teste | D44: =Dados!D29 -> 850 | E44: =$B$4*D44+(1-$B$4)*(E43+F43) -> 678.69049 | F44: =$B$5*(E44-E43)+(1-$B$5)*F43 -> 37.445178 | G44: =E43+F43 -> 624.59275 | H44: =D44-G44 -> 225.40725 | I44: =ABS(H44) -> 225.40725 | J44: =H44^2 -> 50808.428 | K44: =I44/D44 -> 0.265185 | L44: =H44/D44 -> 0.265185 | M44: =$E$43+(A44-24)*$F$43 -> 624.59275 | N44: =D44-M44 -> 225.40725 | O44: =ABS(N44) -> 225.40725 | P44: =N44^2 -> 50808.428 | Q44: =O44/D44 -> 0.265185 | R44: =N44/D44 -> 0.265185
A45: 26 | B45: 1996-T2 | C45: Teste | D45: =Dados!D30 -> 600 | E45: =$B$4*D45+(1-$B$4)*(E44+F44) -> 688.26311 | F45: =$B$5*(E45-E44)+(1-$B$5)*F44 -> 30.477038 | G45: =E44+F44 -> 716.13567 | H45: =D45-G45 -> -116.13567 | I45: =ABS(H45) -> 116.13567 | J45: =H45^2 -> 13487.494 | K45: =I45/D45 -> 0.19355945 | L45: =H45/D45 -> -0.19355945 | M45: =$E$43+(A45-24)*$F$43 -> 648.51349 | N45: =D45-M45 -> -48.513494 | O45: =ABS(N45) -> 48.513494 | P45: =N45^2 -> 2353.5591 | Q45: =O45/D45 -> 0.080855824 | R45: =N45/D45 -> -0.080855824
A46: 27 | B46: 1996-T3 | C46: Teste | D46: =Dados!D31 -> 450 | E46: =$B$4*D46+(1-$B$4)*(E45+F45) -> 654.24251 | F46: =$B$5*(E46-E45)+(1-$B$5)*F45 -> 14.352629 | G46: =E45+F45 -> 718.74015 | H46: =D46-G46 -> -268.74015 | I46: =ABS(H46) -> 268.74015 | J46: =H46^2 -> 72221.266 | K46: =I46/D46 -> 0.59720033 | L46: =H46/D46 -> -0.59720033 | M46: =$E$43+(A46-24)*$F$43 -> 672.43424 | N46: =D46-M46 -> -222.43424 | O46: =ABS(N46) -> 222.43424 | P46: =N46^2 -> 49476.99 | Q46: =O46/D46 -> 0.49429831 | R46: =N46/D46 -> -0.49429831
A47: 28 | B47: 1996-T4 | C47: Teste | D47: =Dados!D32 -> 700 | E47: =$B$4*D47+(1-$B$4)*(E46+F46) -> 676.13231 | F47: =$B$5*(E47-E46)+(1-$B$5)*F46 -> 16.236921 | G47: =E46+F46 -> 668.59514 | H47: =D47-G47 -> 31.404859 | I47: =ABS(H47) -> 31.404859 | J47: =H47^2 -> 986.2652 | K47: =I47/D47 -> 0.044864085 | L47: =H47/D47 -> 0.044864085 | M47: =$E$43+(A47-24)*$F$43 -> 696.35498 | N47: =D47-M47 -> 3.6450192 | O47: =ABS(N47) -> 3.6450192 | P47: =N47^2 -> 13.286165 | Q47: =O47/D47 -> 0.0052071703 | R47: =N47/D47 -> 0.0052071703

Sheet HoltWinters
A1: Holt-Winters multiplicativo (L = 4) — demanda de reparo naval
A2: A(t)=α·Y(t)/S(t−L)+(1−α)[A(t−1)+T(t−1)] | T(t)=β[A(t)−A(t−1)]+(1−β)T(t−1) | S(t)=γ·Y(t)/A(t)+(1−γ)S(t−L) | Ŷ(t+p)=[A(t)+p·T(t)]·S(t−L+p)
A4: α (nível) | B4: 0.8 | C4: ← parâmetros dos slides
A5: β (tendência) | B5: 0.1
A6: γ (sazonalidade) | B6: 0.3 | C6: ← ótimo do treino no notebook: (0,85; 0,10; 0,95)
A7: Início: A(4)=média(Y1..Y4); T(4)=[média(Y5..Y8)−média(Y1..Y4)]/4; S(1..4)=Y(i)/A(4).
A10: Medida | B10: TREINO (ajuste, t=5–24) | C10: TESTE A (origem fixa) | D10: TESTE B (rolling)
A11: MAD | B11: =AVERAGE(J24:J43) -> 46.345866 | C11: =AVERAGE(P44:P47) -> 31.386021 | D11: =AVERAGE(J44:J47) -> 29.288872 | F11: ← Solver: minimizar B16 (SSE do treino) alterando B4:B6 (use Multistart)
A12: MSE | B12: =AVERAGE(K24:K43) -> 4332.4689 | C12: =AVERAGE(Q44:Q47) -> 1218.2322 | D12: =AVERAGE(K44:K47) -> 1621.4279
A13: RMSE | B13: =SQRT(AVERAGE(K24:K43)) -> 65.821493 | C13: =SQRT(AVERAGE(Q44:Q47)) -> 34.903183 | D13: =SQRT(AVERAGE(K44:K47)) -> 40.266958 | F13: Índices sazonais finais S25..S28 → | J13: =G44 -> 1.3342578 | K13: =G45 -> 0.9242392 | L13: =G46 -> 0.67393805 | M13: =G47 -> 1.1070225
A14: MAPE | B14: =AVERAGE(L24:L43) -> 0.11540975 | C14: =AVERAGE(R44:R47) -> 0.04922664 | D14: =AVERAGE(L44:L47) -> 0.038990888
A15: MPE | B15: =AVERAGE(M24:M43) -> 0.028879846 | C15: =AVERAGE(S44:S47) -> 0.042094631 | D15: =AVERAGE(M44:M47) -> -0.0043777971
A16: SSE | B16: =SUM(K24:K43) -> 86649.379 | C16: =SUM(Q44:Q47) -> 4872.9288 | D16: =SUM(K44:K47) -> 6485.7115
A17: n | B17: =COUNT(K24:K43) -> 20 | C17: =COUNT(Q44:Q47) -> 4 | D17: =COUNT(K44:K47) -> 4
A19: t | B19: Rótulo | C19: Conjunto | D19: Y | E19: A(t) nível | F19: T(t) tendência | G19: S(t) índice sazonal | H19: Ŷ(t)=[A(t−1)+T(t−1)]·S(t−4) (1 passo, rolling) | I19: Erro e = Y − Ŷ | J19: |e| | K19: e² | L19: |e|/Y | M19: e/Y | N19: Ŷ origem fixa (t=24) =[A24+p·T24]·S(20+p) | O19: Erro e = Y − Ŷ | P19: |e| | Q19: e² | R19: |e|/Y | S19: e/Y | T19: Previsão operacional 1997 =[A28+p·T28]·S(24+p)
A20: 1 | B20: 1990-T1 | C20: Treino | D20: =Dados!D5 -> 500 | G20: =D20/AVERAGE($D$20:$D$23) -> 1.3333333
A21: 2 | B21: 1990-T2 | C21: Treino | D21: =Dados!D6 -> 350 | G21: =D21/AVERAGE($D$20:$D$23) -> 0.93333333
A22: 3 | B22: 1990-T3 | C22: Treino | D22: =Dados!D7 -> 250 | G22: =D22/AVERAGE($D$20:$D$23) -> 0.66666667
A23: 4 | B23: 1990-T4 | C23: Treino | D23: =Dados!D8 -> 400 | E23: =AVERAGE(D20:D23) -> 375 | F23: =(AVERAGE(D24:D27)-AVERAGE(D20:D23))/4 -> -12.5 | G23: =D23/AVERAGE($D$20:$D$23) -> 1.0666667
A24: 5 | B24: 1991-T1 | C24: Treino | D24: =Dados!D9 -> 450 | E24: =$B$4*D24/G20+(1-$B$4)*(E23+F23) -> 342.5 | F24: =$B$5*(E24-E23)+(1-$B$5)*F23 -> -14.5 | G24: =$B$6*D24/E24+(1-$B$6)*G20 -> 1.3274939 | H24: =(E23+F23)*G20 -> 483.33333 | I24: =D24-H24 -> -33.333333 | J24: =ABS(I24) -> 33.333333 | K24: =I24^2 -> 1111.1111 | L24: =J24/D24 -> 0.074074074 | M24: =I24/D24 -> -0.074074074
A25: 6 | B25: 1991-T2 | C25: Treino | D25: =Dados!D10 -> 350 | E25: =$B$4*D25/G21+(1-$B$4)*(E24+F24) -> 365.6 | F25: =$B$5*(E25-E24)+(1-$B$5)*F24 -> -10.74 | G25: =$B$6*D25/E25+(1-$B$6)*G21 -> 0.94053246 | H25: =(E24+F24)*G21 -> 306.13333 | I25: =D25-H25 -> 43.866667 | J25: =ABS(I25) -> 43.866667 | K25: =I25^2 -> 1924.2844 | L25: =J25/D25 -> 0.12533333 | M25: =I25/D25 -> 0.12533333
A26: 7 | B26: 1991-T3 | C26: Treino | D26: =Dados!D11 -> 200 | E26: =$B$4*D26/G22+(1-$B$4)*(E25+F25) -> 310.972 | F26: =$B$5*(E26-E25)+(1-$B$5)*F25 -> -15.1288 | G26: =$B$6*D26/E26+(1-$B$6)*G22 -> 0.65961008 | H26: =(E25+F25)*G22 -> 236.57333 | I26: =D26-H26 -> -36.573333 | J26: =ABS(I26) -> 36.573333 | K26: =I26^2 -> 1337.6087 | L26: =J26/D26 -> 0.18286667 | M26: =I26/D26 -> -0.18286667
A27: 8 | B27: 1991-T4 | C27: Treino | D27: =Dados!D12 -> 300 | E27: =$B$4*D27/G23+(1-$B$4)*(E26+F26) -> 284.16864 | F27: =$B$5*(E27-E26)+(1-$B$5)*F26 -> -16.296256 | G27: =$B$6*D27/E27+(1-$B$6)*G23 -> 1.06338 | H27: =(E26+F26)*G23 -> 315.56608 | I27: =D27-H27 -> -15.56608 | J27: =ABS(I27) -> 15.56608 | K27: =I27^2 -> 242.30285 | L27: =J27/D27 -> 0.051886933 | M27: =I27/D27 -> -0.051886933
A28: 9 | B28: 1992-T1 | C28: Treino | D28: =Dados!D13 -> 350 | E28: =$B$4*D28/G24+(1-$B$4)*(E27+F27) -> 264.49823 | F28: =$B$5*(E28-E27)+(1-$B$5)*F27 -> -16.633671 | G28: =$B$6*D28/E28+(1-$B$6)*G24 -> 1.3262238 | H28: =(E27+F27)*G24 -> 355.59896 | I28: =D28-H28 -> -5.5989604 | J28: =ABS(I28) -> 5.5989604 | K28: =I28^2 -> 31.348357 | L28: =J28/D28 -> 0.01599703 | M28: =I28/D28 -> -0.01599703
A29: 10 | B29: 1992-T2 | C29: Treino | D29: =Dados!D14 -> 200 | E29: =$B$4*D29/G25+(1-$B$4)*(E28+F28) -> 219.68932 | F29: =$B$5*(E29-E28)+(1-$B$5)*F28 -> -19.451196 | G29: =$B$6*D29/E29+(1-$B$6)*G25 -> 0.93148568 | H29: =(E28+F28)*G25 -> 233.12466 | I29: =D29-H29 -> -33.124663 | J29: =ABS(I29) -> 33.124663 | K29: =I29^2 -> 1097.2433 | L29: =J29/D29 -> 0.16562332 | M29: =I29/D29 -> -0.16562332
A30: 11 | B30: 1992-T3 | C30: Treino | D30: =Dados!D15 -> 150 | E30: =$B$4*D30/G26+(1-$B$4)*(E29+F29) -> 221.97328 | F30: =$B$5*(E30-E29)+(1-$B$5)*F29 -> -17.277679 | G30: =$B$6*D30/E30+(1-$B$6)*G26 -> 0.66445416 | H30: =(E29+F29)*G26 -> 132.07908 | I30: =D30-H30 -> 17.920917 | J30: =ABS(I30) -> 17.920917 | K30: =I30^2 -> 321.15926 | L30: =J30/D30 -> 0.11947278 | M30: =I30/D30 -> 0.11947278
A31: 12 | B31: 1992-T4 | C31: Treino | D31: =Dados!D16 -> 400 | E31: =$B$4*D31/G27+(1-$B$4)*(E30+F30) -> 341.86635 | F31: =$B$5*(E31-E30)+(1-$B$5)*F30 -> -3.5606047 | G31: =$B$6*D31/E31+(1-$B$6)*G27 -> 1.0953804 | H31: =(E30+F30)*G27 -> 217.66921 | I31: =D31-H31 -> 182.33079 | J31: =ABS(I31) -> 182.33079 | K31: =I31^2 -> 33244.515 | L31: =J31/D31 -> 0.45582696 | M31: =I31/D31 -> 0.45582696
A32: 13 | B32: 1993-T1 | C32: Treino | D32: =Dados!D17 -> 550 | E32: =$B$4*D32/G28+(1-$B$4)*(E31+F31) -> 399.43019 | F32: =$B$5*(E32-E31)+(1-$B$5)*F31 -> 2.5518393 | G32: =$B$6*D32/E32+(1-$B$6)*G28 -> 1.3414451 | H32: =(E31+F31)*G28 -> 448.66914 | I32: =D32-H32 -> 101.33086 | J32: =ABS(I32) -> 101.33086 | K32: =I32^2 -> 10267.943 | L32: =J32/D32 -> 0.18423793 | M32: =I32/D32 -> 0.18423793
A33: 14 | B33: 1993-T2 | C33: Treino | D33: =Dados!D18 -> 350 | E33: =$B$4*D33/G29+(1-$B$4)*(E32+F32) -> 380.99147 | F33: =$B$5*(E33-E32)+(1-$B$5)*F32 -> 0.45278382 | G33: =$B$6*D33/E33+(1-$B$6)*G29 -> 0.9276367 | H33: =(E32+F32)*G29 -> 374.4405 | I33: =D33-H33 -> -24.440501 | J33: =ABS(I33) -> 24.440501 | K33: =I33^2 -> 597.33809 | L33: =J33/D33 -> 0.069830003 | M33: =I33/D33 -> -0.069830003
A34: 15 | B34: 1993-T3 | C34: Treino | D34: =Dados!D19 -> 250 | E34: =$B$4*D34/G30+(1-$B$4)*(E33+F33) -> 377.2878 | F34: =$B$5*(E34-E33)+(1-$B$5)*F33 -> 0.03713795 | G34: =$B$6*D34/E34+(1-$B$6)*G30 -> 0.66390515 | H34: =(E33+F33)*G30 -> 253.45222 | I34: =D34-H34 -> -3.4522204 | J34: =ABS(I34) -> 3.4522204 | K34: =I34^2 -> 11.917825 | L34: =J34/D34 -> 0.013808881 | M34: =I34/D34 -> -0.013808881
A35: 16 | B35: 1993-T4 | C35: Treino | D35: =Dados!D20 -> 550 | E35: =$B$4*D35/G31+(1-$B$4)*(E34+F34) -> 477.15194 | F35: =$B$5*(E35-E34)+(1-$B$5)*F34 -> 10.019838 | G35: =$B$6*D35/E35+(1-$B$6)*G31 -> 1.1125681 | H35: =(E34+F34)*G31 -> 413.31433 | I35: =D35-H35 -> 136.68567 | J35: =ABS(I35) -> 136.68567 | K35: =I35^2 -> 18682.973 | L35: =J35/D35 -> 0.24851941 | M35: =I35/D35 -> 0.24851941
... A43: 24 | B43: 1995-T4 | C43: Treino | D43: =Dados!D28 -> 650 | E43: =$B$4*D43/G39+(1-$B$4)*(E42+F42) -> 586.92145 | F43: =$B$5*(E43-E42)+(1-$B$5)*F42 -> 12.786011 | G43: =$B$6*D43/E43+(1-$B$6)*G39 -> 1.1127146 | H43: =(E42+F42)*G39 -> 671.97204 | I43: =D43-H43 -> -21.972044 | J43: =ABS(I43) -> 21.972044 | K43: =I43^2 -> 482.77074 | L43: =J43/D43 -> 0.033803145 | M43: =I43/D43 -> -0.033803145
A44: 25 | B44: 1996-T1 | C44: Teste | D44: =Dados!D29 -> 850 | E44: =$B$4*D44/G40+(1-$B$4)*(E43+F43) -> 631.51321 | F44: =$B$5*(E44-E43)+(1-$B$5)*F43 -> 15.966586 | G44: =$B$6*D44/E44+(1-$B$6)*G40 -> 1.3342578 | H44: =(E43+F43)*G40 -> 797.15328 | I44: =D44-H44 -> 52.846723 | J44: =ABS(I44) -> 52.846723 | K44: =I44^2 -> 2792.7762 | L44: =J44/D44 -> 0.062172616 | M44: =I44/D44 -> 0.062172616 | N44: =($E$43+(A44-24)*$F$43)*G40 -> 797.15328 | O44: =D44-N44 -> 52.846723 | P44: =ABS(O44) -> 52.846723 | Q44: =O44^2 -> 2792.7762 | R44: =P44/D44 -> 0.062172616 | S44: =O44/D44 -> 0.062172616
A45: 26 | B45: 1996-T2 | C45: Teste | D45: =Dados!D30 -> 600 | E45: =$B$4*D45/G41+(1-$B$4)*(E44+F44) -> 648.92902 | F45: =$B$5*(E45-E44)+(1-$B$5)*F44 -> 16.111508 | G45: =$B$6*D45/E45+(1-$B$6)*G41 -> 0.9242392 | H45: =(E44+F44)*G41 -> 598.326 | I45: =D45-H45 -> 1.6740022 | J45: =ABS(I45) -> 1.6740022 | K45: =I45^2 -> 2.8022834 | L45: =J45/D45 -> 0.0027900037 | M45: =I45/D45 -> 0.0027900037 | N45: =($E$43+(A45-24)*$F$43)*G41 -> 565.99568 | O45: =D45-N45 -> 34.004322 | P45: =ABS(O45) -> 34.004322 | Q45: =O45^2 -> 1156.2939 | R45: =P45/D45 -> 0.05667387 | S45: =O45/D45 -> 0.05667387
A46: 27 | B46: 1996-T3 | C46: Teste | D46: =Dados!D31 -> 450 | E46: =$B$4*D46/G42+(1-$B$4)*(E45+F45) -> 667.3186 | F46: =$B$5*(E46-E45)+(1-$B$5)*F45 -> 16.339315 | G46: =$B$6*D46/E46+(1-$B$6)*G42 -> 0.67393805 | H46: =(E45+F45)*G42 -> 448.0814 | I46: =D46-H46 -> 1.9186031 | J46: =ABS(I46) -> 1.9186031 | K46: =I46^2 -> 3.6810379 | L46: =J46/D46 -> 0.0042635625 | M46: =I46/D46 -> 0.0042635625 | N46: =($E$43+(A46-24)*$F$43)*G42 -> 421.29177 | O46: =D46-N46 -> 28.708225 | P46: =ABS(O46) -> 28.708225 | Q46: =O46^2 -> 824.16219 | R46: =P46/D46 -> 0.063796056 | S46: =O46/D46 -> 0.063796056
A47: 28 | B47: 1996-T4 | C47: Teste | D47: =Dados!D32 -> 700 | E47: =$B$4*D47/G43+(1-$B$4)*(E46+F46) -> 640.00527 | F47: =$B$5*(E47-E46)+(1-$B$5)*F46 -> 11.974051 | G47: =$B$6*D47/E47+(1-$B$6)*G43 -> 1.1070225 | H47: =(E46+F46)*G43 -> 760.71616 | I47: =D47-H47 -> -60.716159 | J47: =ABS(I47) -> 60.716159 | K47: =I47^2 -> 3686.452 | L47: =J47/D47 -> 0.08673737 | M47: =I47/D47 -> -0.08673737 | N47: =($E$43+(A47-24)*$F$43)*G43 -> 709.98481 | O47: =D47-N47 -> -9.9848124 | P47: =ABS(O47) -> 9.9848124 | Q47: =O47^2 -> 99.69648 | R47: =P47/D47 -> 0.014264018 | S47: =O47/D47 -> -0.014264018
A48: 29 | B48: 1997-T1 | C48: Futuro | T48: =($E$47+(A48-28)*$F$47)*G44 -> 869.90853
A49: 30 | B49: 1997-T2 | C49: Futuro | T49: =($E$47+(A49-28)*$F$47)*G45 -> 613.65174
A50: 31 | B50: 1997-T3 | C50: Futuro | T50: =($E$47+(A50-28)*$F$47)*G46 -> 455.53322
A51: 32 | B51: 1997-T4 | C51: Futuro | T51: =($E$47+(A51-28)*$F$47)*G47 -> 761.52244

Sheet Comparacao
A1: Comparação: SES × Holt × Holt-Winters — mesmo dataset (reparo naval), mesmo teste (t = 25–28)
A2: Valores lidos das outras abas: mude os parâmetros lá e esta tabela se atualiza.
A4: Método | B4: α | C4: β | D4: γ | E4: MSE ajuste (treino) | F4: MSE teste A (origem fixa) | G4: MSE teste B (rolling) | H4: MAPE teste A | I4: Teste B / ajuste | J4: O que captura
A5: SES | B5: =SES!B4 -> 0.33540571 | C5: — | D5: — | E5: =SES!B12 -> 21420.14 | F5: =SES!C12 -> 31848.554 | G5: =SES!D12 -> 35997.047 | H5: =SES!C14 -> 0.21970674 | I5: =G5/E5 -> 1.6805235 | J5: nível
A6: Holt | B6: =Holt_Reparo!B4 -> 0.24 | C6: =Holt_Reparo!B5 -> 0.25 | D6: — | E6: =Holt_Reparo!B12 -> 22178.797 | F6: =Holt_Reparo!C12 -> 25663.066 | G6: =Holt_Reparo!D12 -> 34375.863 | H6: =Holt_Reparo!C14 -> 0.21138657 | I6: =G6/E6 -> 1.5499427 | J6: nível + tendência
A7: Holt-Winters | B7: =HoltWinters!B4 -> 0.8 | C7: =HoltWinters!B5 -> 0.1 | D7: =HoltWinters!B6 -> 0.3 | E7: =HoltWinters!B12 -> 4332.4689 | F7: =HoltWinters!C12 -> 1218.2322 | G7: =HoltWinters!D12 -> 1621.4279 | H7: =HoltWinters!C14 -> 0.04922664 | I7: =G7/E7 -> 0.37425032 | J7: nível + tendência + sazonalidade
A9: Leituras-chave
A10: 1. SES e Holt têm erro de teste da ordem de dezenas de milhares: nenhum dos dois modela a sazonalidade.
A11: 2. O Holt-Winters reduz o erro de teste em mais de 20 vezes: é o único que modela tendência E sazonalidade.
